Workbook

Sheet 00_INDICE
A1: Hoja | B1: Rol | C1: Origen
A2: 01_PRODUCTOS | B2: ENTRADA_PYTHON | C2: OPERATIVA 02_PRODUCTOS
A3: 02_MATERIALES | B3: REFERENCIA | C3: OPERATIVA 03_MATERIALES
A4: 03_DESPIECE | B4: ENTRADA_PYTHON (opcional) | C4: OPERATIVA 04_DESPIECE (valores materializados)
A5: 04_MAQUINAS | B5: ENTRADA_PYTHON | C5: OPERATIVA 05_RECURSOS
A6: 05_RUTAS | B6: ENTRADA_PYTHON | C6: OPERATIVA 06_RUTAS
A7: 06B_HABILIDADES | B7: ENTRADA_PYTHON | C7: SIMULACION 03_HABILIDADES_SIM
A8: 06_OPERARIOS | B8: ENTRADA_PYTHON | C8: OPERATIVA 08_PERSONAL + SIMULACION 02_PERFILES_SIM
A9: 07_CALENDARIO | B9: ENTRADA_PYTHON | C9: OPERATIVA 09_CALENDARIO
A10: 08_PEDIDOS | B10: ENTRADA_PYTHON | C10: SIMULACION 01_PEDIDOS_SIM
A11: 09_CARGA_ORDEN | B11: DERIVADA (fórmulas) | C11: 08_PEDIDOS × 05_RUTAS
A12: 10_MATERIALES_ORDEN | B12: DERIVADA (fórmulas) | C12: 08_PEDIDOS × 03_DESPIECE
... A29: Naturaleza | B29: REAL / REFERENCIA / CALCULADO / ESTIMADO / SIMULADO / CONFIGURACION / PENDIENTE | C29: Definiciones en SAGAPI_BD_OPERATIVA_v2_0.xlsx, hoja 00_CODIGOS

Sheet 01_PRODUCTOS
A1: Familia | B1: Nombre completo | C1: Tipo | D1: Alto cm | E1: Ancho cm | F1: Fondo cm | G1: Puertas | H1: Lote guía | I1: Componentes | J1: Pasos de ruta | K1: Familia válida (1/0) | L1: Dimensiones genéricas (1/0) | M1: Naturaleza
A2: Racks industriales | B2: Minirack metálico con bandejas | C2: Estantería liviana | D2: 200 | E2: 120 | F2: 60 | H2: 10 | I2: =COUNTIF('03_DESPIECE'!$A$2:$A$225,B2) -> 7 | J2: =COUNTIF('05_RUTAS'!$A$2:$A$407,B2) -> 13 | K2: =IF(COUNTIF('12_PRECIOS'!$A$2:$A$5,A2)>0,1,0) -> 1 | L2: =IF(COUNTIFS($D$2:$D$51,D2,$E$2:$E$51,E2,$F$2:$F$51,F2)>=5,1,0) -> 0 | M2: ESTIMADO
A3: Racks industriales | B3: Estante reforzado modular | C3: Estantería reforzada | D3: 200 | E3: 120 | F3: 60 | H3: 10 | I3: =COUNTIF('03_DESPIECE'!$A$2:$A$225,B3) -> 6 | J3: =COUNTIF('05_RUTAS'!$A$2:$A$407,B3) -> 13 | K3: =IF(COUNTIF('12_PRECIOS'!$A$2:$A$5,A3)>0,1,0) -> 1 | L3: =IF(COUNTIFS($D$2:$D$51,D3,$E$2:$E$51,E3,$F$2:$F$51,F3)>=5,1,0) -> 0 | M3: ESTIMADO
A4: Racks industriales | B4: Rack selectivo para pallets | C4: Selectivo | D4: 400 | E4: 270 | F4: 110 | H4: 10 | I4: =COUNTIF('03_DESPIECE'!$A$2:$A$225,B4) -> 4 | J4: =COUNTIF('05_RUTAS'!$A$2:$A$407,B4) -> 8 | K4: =IF(COUNTIF('12_PRECIOS'!$A$2:$A$5,A4)>0,1,0) -> 1 | L4: =IF(COUNTIFS($D$2:$D$51,D4,$E$2:$E$51,E4,$F$2:$F$51,F4)>=5,1,0) -> 0 | M4: ESTIMADO
A5: Racks industriales | B5: Rack cantilever 3 niveles | C5: Cantilever | D5: 300 | E5: 150 | F5: 100 | H5: 10 | I5: =COUNTIF('03_DESPIECE'!$A$2:$A$225,B5) -> 4 | J5: =COUNTIF('05_RUTAS'!$A$2:$A$407,B5) -> 8 | K5: =IF(COUNTIF('12_PRECIOS'!$A$2:$A$5,A5)>0,1,0) -> 1 | L5: =IF(COUNTIFS($D$2:$D$51,D5,$E$2:$E$51,E5,$F$2:$F$51,F5)>=5,1,0) -> 0 | M5: ESTIMADO
A6: Racks industriales | B6: Estantería metálica K45 5 niveles | C6: Picking | D6: 200 | E6: 120 | F6: 60 | H6: 10 | I6: =COUNTIF('03_DESPIECE'!$A$2:$A$225,B6) -> 4 | J6: =COUNTIF('05_RUTAS'!$A$2:$A$407,B6) -> 10 | K6: =IF(COUNTIF('12_PRECIOS'!$A$2:$A$5,A6)>0,1,0) -> 1 | L6: =IF(COUNTIFS($D$2:$D$51,D6,$E$2:$E$51,E6,$F$2:$F$51,F6)>=5,1,0) -> 0 | M6: ESTIMADO
A7: Racks industriales | B7: Rack Mecano Strong MY-075-1 | C7: Semindustrial | D7: 200 | E7: 120 | F7: 60 | H7: 10 | I7: =COUNTIF('03_DESPIECE'!$A$2:$A$225,B7) -> 4 | J7: =COUNTIF('05_RUTAS'!$A$2:$A$407,B7) -> 8 | K7: =IF(COUNTIF('12_PRECIOS'!$A$2:$A$5,A7)>0,1,0) -> 1 | L7: =IF(COUNTIFS($D$2:$D$51,D7,$E$2:$E$51,E7,$F$2:$F$51,F7)>=5,1,0) -> 0 | M7: ESTIMADO
A8: Góndolas comerciales | B8: Góndola central comercial | C8: Góndola central | D8: 160 | E8: 100 | F8: 90 | H8: 10 | I8: =COUNTIF('03_DESPIECE'!$A$2:$A$225,B8) -> 7 | J8: =COUNTIF('05_RUTAS'!$A$2:$A$407,B8) -> 12 | K8: =IF(COUNTIF('12_PRECIOS'!$A$2:$A$5,A8)>0,1,0) -> 1 | L8: =IF(COUNTIFS($D$2:$D$51,D8,$E$2:$E$51,E8,$F$2:$F$51,F8)>=5,1,0) -> 0 | M8: ESTIMADO
A9: Góndolas comerciales | B9: Góndola mural | C9: Góndola mural | D9: 200 | E9: 100 | F9: 45 | H9: 10 | I9: =COUNTIF('03_DESPIECE'!$A$2:$A$225,B9) -> 6 | J9: =COUNTIF('05_RUTAS'!$A$2:$A$407,B9) -> 13 | K9: =IF(COUNTIF('12_PRECIOS'!$A$2:$A$5,A9)>0,1,0) -> 1 | L9: =IF(COUNTIFS($D$2:$D$51,D9,$E$2:$E$51,E9,$F$2:$F$51,F9)>=5,1,0) -> 0 | M9: ESTIMADO
A10: Góndolas comerciales | B10: Góndola central doble forro liso | C10: Central | D10: 160 | E10: 100 | F10: 90 | H10: 10 | I10: =COUNTIF('03_DESPIECE'!$A$2:$A$225,B10) -> 5 | J10: =COUNTIF('05_RUTAS'!$A$2:$A$407,B10) -> 10 | K10: =IF(COUNTIF('12_PRECIOS'!$A$2:$A$5,A10)>0,1,0) -> 1 | L10: =IF(COUNTIFS($D$2:$D$51,D10,$E$2:$E$51,E10,$F$2:$F$51,F10)>=5,1,0) -> 0 | M10: ESTIMADO
A11: Góndolas comerciales | B11: Góndola mural de forro liso | C11: Pared | D11: 200 | E11: 100 | F11: 45 | H11: 10 | I11: =COUNTIF('03_DESPIECE'!$A$2:$A$225,B11) -> 5 | J11: =COUNTIF('05_RUTAS'!$A$2:$A$407,B11) -> 10 | K11: =IF(COUNTIF('12_PRECIOS'!$A$2:$A$5,A11)>0,1,0) -> 1 | L11: =IF(COUNTIFS($D$2:$D$51,D11,$E$2:$E$51,E11,$F$2:$F$51,F11)>=5,1,0) -> 0 | M11: ESTIMADO
A12: Góndolas comerciales | B12: Góndola de cabecera liso | C12: Cabecera | D12: 150 | E12: 90 | F12: 45 | H12: 10 | I12: =COUNTIF('03_DESPIECE'!$A$2:$A$225,B12) -> 5 | J12: =COUNTIF('05_RUTAS'!$A$2:$A$407,B12) -> 10 | K12: =IF(COUNTIF('12_PRECIOS'!$A$2:$A$5,A12)>0,1,0) -> 1 | L12: =IF(COUNTIFS($D$2:$D$51,D12,$E$2:$E$51,E12,$F$2:$F$51,F12)>=5,1,0) -> 0 | M12: ESTIMADO
A13: Góndolas comerciales | B13: Góndola isla modular | C13: Isla | D13: 160 | E13: 100 | F13: 90 | H13: 10 | I13: =COUNTIF('03_DESPIECE'!$A$2:$A$225,B13) -> 5 | J13: =COUNTIF('05_RUTAS'!$A$2:$A$407,B13) -> 10 | K13: =IF(COUNTIF('12_PRECIOS'!$A$2:$A$5,A13)>0,1,0) -> 1 | L13: =IF(COUNTIFS($D$2:$D$51,D13,$E$2:$E$51,E13,$F$2:$F$51,F13)>=5,1,0) -> 0 | M13: ESTIMADO
A14: Lockers metálicos | B14: Locker de 4 puertas | C14: Locker de 4 compartimentos | D14: 180 | E14: 80 | F14: 45 | G14: 4 | H14: 10 | I14: =COUNTIF('03_DESPIECE'!$A$2:$A$225,B14) -> 7 | J14: =COUNTIF('05_RUTAS'!$A$2:$A$407,B14) -> 11 | K14: =IF(COUNTIF('12_PRECIOS'!$A$2:$A$5,A14)>0,1,0) -> 1 | L14: =IF(COUNTIFS($D$2:$D$51,D14,$E$2:$E$51,E14,$F$2:$F$51,F14)>=5,1,0) -> 0 | M14: ESTIMADO
A15: Lockers metálicos | B15: Locker de 6 puertas | C15: Locker de 6 compartimentos | D15: 180 | E15: 80 | F15: 45 | G15: 6 | H15: 10 | I15: =COUNTIF('03_DESPIECE'!$A$2:$A$225,B15) -> 8 | J15: =COUNTIF('05_RUTAS'!$A$2:$A$407,B15) -> 11 | K15: =IF(COUNTIF('12_PRECIOS'!$A$2:$A$5,A15)>0,1,0) -> 1 | L15: =IF(COUNTIFS($D$2:$D$51,D15,$E$2:$E$51,E15,$F$2:$F$51,F15)>=5,1,0) -> 0 | M15: ESTIMADO
A16: Lockers metálicos | B16: Locker metálico simple MK1-01 | C16: 1 puertas | D16: 180 | E16: 40 | F16: 45 | G16: 1 | H16: 10 | I16: =COUNTIF('03_DESPIECE'!$A$2:$A$225,B16) -> 5 | J16: =COUNTIF('05_RUTAS'!$A$2:$A$407,B16) -> 8 | K16: =IF(COUNTIF('12_PRECIOS'!$A$2:$A$5,A16)>0,1,0) -> 1 | L16: =IF(COUNTIFS($D$2:$D$51,D16,$E$2:$E$51,E16,$F$2:$F$51,F16)>=5,1,0) -> 0 | M16: ESTIMADO
A17: Lockers metálicos | B17: Locker metálico simple MK2-01 | C17: 2 puertas | D17: 180 | E17: 40 | F17: 45 | G17: 2 | H17: 10 | I17: =COUNTIF('03_DESPIECE'!$A$2:$A$225,B17) -> 5 | J17: =COUNTIF('05_RUTAS'!$A$2:$A$407,B17) -> 8 | K17: =IF(COUNTIF('12_PRECIOS'!$A$2:$A$5,A17)>0,1,0) -> 1 | L17: =IF(COUNTIFS($D$2:$D$51,D17,$E$2:$E$51,E17,$F$2:$F$51,F17)>=5,1,0) -> 0 | M17: ESTIMADO
A18: Lockers metálicos | B18: Locker metálico simple MK3-01 | C18: 3 puertas | D18: 180 | E18: 40 | F18: 45 | G18: 3 | H18: 10 | I18: =COUNTIF('03_DESPIECE'!$A$2:$A$225,B18) -> 5 | J18: =COUNTIF('05_RUTAS'!$A$2:$A$407,B18) -> 8 | K18: =IF(COUNTIF('12_PRECIOS'!$A$2:$A$5,A18)>0,1,0) -> 1 | L18: =IF(COUNTIFS($D$2:$D$51,D18,$E$2:$E$51,E18,$F$2:$F$51,F18)>=5,1,0) -> 0 | M18: ESTIMADO
A19: Lockers metálicos | B19: Locker metálico simple MK4-01 | C19: 4 puertas | D19: 180 | E19: 40 | F19: 45 | G19: 4 | H19: 10 | I19: =COUNTIF('03_DESPIECE'!$A$2:$A$225,B19) -> 5 | J19: =COUNTIF('05_RUTAS'!$A$2:$A$407,B19) -> 8 | K19: =IF(COUNTIF('12_PRECIOS'!$A$2:$A$5,A19)>0,1,0) -> 1 | L19: =IF(COUNTIFS($D$2:$D$51,D19,$E$2:$E$51,E19,$F$2:$F$51,F19)>=5,1,0) -> 0 | M19: ESTIMADO
A20: Otros productos metalmecánicos | B20: Armario metálico | C20: Gabinete metálico | D20: 85 | E20: 120 | F20: 60 | H20: 10 | I20: =COUNTIF('03_DESPIECE'!$A$2:$A$225,B20) -> 7 | J20: =COUNTIF('05_RUTAS'!$A$2:$A$407,B20) -> 11 | K20: =IF(COUNTIF('12_PRECIOS'!$A$2:$A$5,A20)>0,1,0) -> 1 | L20: =IF(COUNTIFS($D$2:$D$51,D20,$E$2:$E$51,E20,$F$2:$F$51,F20)>=5,1,0) -> 1 | M20: ESTIMADO
A21: Otros productos metalmecánicos | B21: Estantería liviana metálica | C21: Estantería liviana | D21: 85 | E21: 120 | F21: 60 | H21: 10 | I21: =COUNTIF('03_DESPIECE'!$A$2:$A$225,B21) -> 5 | J21: =COUNTIF('05_RUTAS'!$A$2:$A$407,B21) -> 12 | K21: =IF(COUNTIF('12_PRECIOS'!$A$2:$A$5,A21)>0,1,0) -> 1 | L21: =IF(COUNTIFS($D$2:$D$51,D21,$E$2:$E$51,E21,$F$2:$F$51,F21)>=5,1,0) -> 1 | M21: ESTIMADO
A22: Otros productos metalmecánicos | B22: Silla fija PC0173 | C22: Silla | D22: 85 | E22: 45 | F22: 50 | H22: 10 | I22: =COUNTIF('03_DESPIECE'!$A$2:$A$225,B22) -> 3 | J22: =COUNTIF('05_RUTAS'!$A$2:$A$407,B22) -> 8 | K22: =IF(COUNTIF('12_PRECIOS'!$A$2:$A$5,A22)>0,1,0) -> 1 | L22: =IF(COUNTIFS($D$2:$D$51,D22,$E$2:$E$51,E22,$F$2:$F$51,F22)>=5,1,0) -> 1 | M22: ESTIMADO
A23: Otros productos metalmecánicos | B23: Silla capacitación 105 | C23: Silla | D23: 85 | E23: 45 | F23: 50 | H23: 10 | I23: =COUNTIF('03_DESPIECE'!$A$2:$A$225,B23) -> 3 | J23: =COUNTIF('05_RUTAS'!$A$2:$A$407,B23) -> 2 | K23: =IF(COUNTIF('12_PRECIOS'!$A$2:$A$5,A23)>0,1,0) -> 1 | L23: =IF(COUNTIFS($D$2:$D$51,D23,$E$2:$E$51,E23,$F$2:$F$51,F23)>=5,1,0) -> 1 | M23: ESTIMADO
A24: Otros productos metalmecánicos | B24: Cajonera metálica P1019 | C24: Archivador | D24: 85 | E24: 120 | F24: 60 | H24: 10 | I24: =COUNTIF('03_DESPIECE'!$A$2:$A$225,B24) -> 4 | J24: =COUNTIF('05_RUTAS'!$A$2:$A$407,B24) -> 8 | K24: =IF(COUNTIF('12_PRECIOS'!$A$2:$A$5,A24)>0,1,0) -> 1 | L24: =IF(COUNTIFS($D$2:$D$51,D24,$E$2:$E$51,E24,$F$2:$F$51,F24)>=5,1,0) -> 1 | M24: ESTIMADO
A25: Otros productos metalmecánicos | B25: Archivador metálico 3 cajones | C25: Archivador | D25: 85 | E25: 120 | F25: 60 | H25: 10 | I25: =COUNTIF('03_DESPIECE'!$A$2:$A$225,B25) -> 4 | J25: =COUNTIF('05_RUTAS'!$A$2:$A$407,B25) -> 8 | K25: =IF(COUNTIF('12_PRECIOS'!$A$2:$A$5,A25)>0,1,0) -> 1 | L25: =IF(COUNTIFS($D$2:$D$51,D25,$E$2:$E$51,E25,$F$2:$F$51,F25)>=5,1,0) -> 1 | M25: ESTIMADO
A26: Otros productos metalmecánicos | B26: Archivador metálico 4 cajones | C26: Archivador | D26: 85 | E26: 120 | F26: 60 | H26: 10 | I26: =COUNTIF('03_DESPIECE'!$A$2:$A$225,B26) -> 4 | J26: =COUNTIF('05_RUTAS'!$A$2:$A$407,B26) -> 8 | K26: =IF(COUNTIF('12_PRECIOS'!$A$2:$A$5,A26)>0,1,0) -> 1 | L26: =IF(COUNTIFS($D$2:$D$51,D26,$E$2:$E$51,E26,$F$2:$F$51,F26)>=5,1,0) -> 1 | M26: ESTIMADO
A27: Otros productos metalmecánicos | B27: Armario metálico KD-034 | C27: Gabinete | D27: 85 | E27: 120 | F27: 60 | H27: 10 | I27: =COUNTIF('03_DESPIECE'!$A$2:$A$225,B27) -> 4 | J27: =COUNTIF('05_RUTAS'!$A$2:$A$407,B27) -> 8 | K27: =IF(COUNTIF('12_PRECIOS'!$A$2:$A$5,A27)>0,1,0) -> 1 | L27: =IF(COUNTIFS($D$2:$D$51,D27,$E$2:$E$51,E27,$F$2:$F$51,F27)>=5,1,0) -> 1 | M27: ESTIMADO
A28: Otros productos metalmecánicos | B28: Banqueta con patas metálicas | C28: Banco | D28: 85 | E28: 120 | F28: 60 | H28: 10 | I28: =COUNTIF('03_DESPIECE'!$A$2:$A$225,B28) -> 4 | J28: =COUNTIF('05_RUTAS'!$A$2:$A$407,B28) -> 8 | K28: =IF(COUNTIF('12_PRECIOS'!$A$2:$A$5,A28)>0,1,0) -> 1 | L28: =IF(COUNTIFS($D$2:$D$51,D28,$E$2:$E$51,E28,$F$2:$F$51,F28)>=5,1,0) -> 1 | M28: ESTIMADO
A29: Otros productos metalmecánicos | B29: Armario herramientas MY-TC-03 | C29: Gabinete | D29: 85 | E29: 120 | F29: 60 | H29: 10 | I29: =COUNTIF('03_DESPIECE'!$A$2:$A$225,B29) -> 4 | J29: =COUNTIF('05_RUTAS'!$A$2:$A$407,B29) -> 8 | K29: =IF(COUNTIF('12_PRECIOS'!$A$2:$A$5,A29)>0,1,0) -> 1 | L29: =IF(COUNTIFS($D$2:$D$51,D29,$E$2:$E$51,E29,$F$2:$F$51,F29)>=5,1,0) -> 1 | M29: ESTIMADO
A30: Otros productos metalmecánicos | B30: Armario herramientas MY-TC-04 | C30: Gabinete | D30: 85 | E30: 120 | F30: 60 | H30: 10 | I30: =COUNTIF('03_DESPIECE'!$A$2:$A$225,B30) -> 4 | J30: =COUNTIF('05_RUTAS'!$A$2:$A$407,B30) -> 8 | K30: =IF(COUNTIF('12_PRECIOS'!$A$2:$A$5,A30)>0,1,0) -> 1 | L30: =IF(COUNTIFS($D$2:$D$51,D30,$E$2:$E$51,E30,$F$2:$F$51,F30)>=5,1,0) -> 1 | M30: ESTIMADO
A31: Otros productos metalmecánicos | B31: Armario herramientas MY-TC-05 | C31: Gabinete | D31: 85 | E31: 120 | F31: 60 | H31: 10 | I31: =COUNTIF('03_DESPIECE'!$A$2:$A$225,B31) -> 4 | J31: =COUNTIF('05_RUTAS'!$A$2:$A$407,B31) -> 8 | K31: =IF(COUNTIF('12_PRECIOS'!$A$2:$A$5,A31)>0,1,0) -> 1 | L31: =IF(COUNTIFS($D$2:$D$51,D31,$E$2:$E$51,E31,$F$2:$F$51,F31)>=5,1,0) -> 1 | M31: ESTIMADO
... A51: Otros productos metalmecánicos | B51: Silla terraza New Bistro | C51: Silla | D51: 85 | E51: 45 | F51: 50 | H51: 10 | I51: =COUNTIF('03_DESPIECE'!$A$2:$A$225,B51) -> 3 | J51: =COUNTIF('05_RUTAS'!$A$2:$A$407,B51) -> 8 | K51: =IF(COUNTIF('12_PRECIOS'!$A$2:$A$5,A51)>0,1,0) -> 1 | L51: =IF(COUNTIFS($D$2:$D$51,D51,$E$2:$E$51,E51,$F$2:$F$51,F51)>=5,1,0) -> 1 | M51: ESTIMADO

Sheet 02_MATERIALES
A1: Material o accesorio (nombre completo) | B1: Clave técnica auxiliar | C1: Grupo | D1: Unidad de costo | E1: Espesor mm | F1: Ancho m | G1: Largo m | H1: Costo unitario S/ | I1: Material genérico (1/0) | J1: Naturaleza
A2: Plancha de acero laminado en caliente de 2 mm, 1.20 × 2.40 m | B2: MAT-LAC2 | C2: CHAPA | D2: kg | E2: 2 | F2: 1.2 | G2: 2.4 | H2: 6.8 | I2: 0 | J2: ESTIMADO
A3: Lámina LAF o acero 1.0 mm (alternativa V4) | B3: MAT-CH-1.0 | C3: CHAPA | D3: kg | E3: 1 | H3: 6.8 | I3: 0 | J3: ESTIMADO
A4: Lámina LAF o acero 1.5 mm (alternativa V4) | B4: MAT-CH-1.5 | C4: CHAPA | D4: kg | E4: 1.5 | H4: 6.8 | I4: 0 | J4: ESTIMADO
A5: Lámina LAF 0.6 mm (catálogo lockers) | B5: MAT-LAF06 | C5: CHAPA | D5: kg | E5: 0.6 | H5: 6.8 | I5: 0 | J5: ESTIMADO
A6: Lámina LAF 0.8 mm (catálogo góndolas) | B6: MAT-LAF08 | C6: CHAPA | D6: kg | E6: 0.8 | H6: 6.8 | I6: 0 | J6: ESTIMADO
A7: Lámina LAF 1.2 mm (taller) | B7: MAT-LAF12 | C7: CHAPA | D7: kg | E7: 1.2 | H7: 6.8 | I7: 0 | J7: ESTIMADO
A8: Tubo o perfil de acero (sección por definir) | B8: MAT-PR-1 | C8: PERFIL | D8: m | H8: 6.1 | I8: 1 | J8: ESTIMADO
A9: Elementos de fijación metálica (tipo por desagregar) | B9: MAT-FIJ | C9: HERRAJE | D9: und | H9: 0.9 | I9: 1 | J9: ESTIMADO
A10: Tablero melamina/MDP 18 mm comprado | B10: MAT-MEL18 | C10: OTRO | D10: und | E10: 18 | I10: 0 | J10: PENDIENTE
A11: Asiento, ruedas, vidrio, PVC o mecanismos comprados | B11: MAT-OTR | C11: OTRO | D11: und | I11: 1 | J11: PENDIENTE
A12: Pintura electrostática en polvo poliéster | B12: COM-001 | C12: PINTURA | D12: kg | I12: 0 | J12: PENDIENTE
A13: Pintura en polvo epoxi-poliéster | B13: COM-002 | C13: PINTURA | D13: kg | I13: 0 | J13: PENDIENTE
A14: Desengrasante industrial | B14: COM-003 | C14: PREPARACION_SUPERFICIAL | D14: l | I14: 0 | J14: PENDIENTE
A15: Disco abrasivo de corte | B15: COM-004 | C15: CONSUMIBLE | D15: und | I15: 0 | J15: PENDIENTE
A16: Disco abrasivo para desbarbado | B16: COM-005 | C16: CONSUMIBLE | D16: und | I16: 0 | J16: PENDIENTE
A17: Alambre para soldadura MIG/MAG | B17: COM-006 | C17: SOLDADURA | D17: kg | I17: 0 | J17: PENDIENTE
A18: Electrodo revestido para soldadura | B18: COM-007 | C18: SOLDADURA | D18: kg | I18: 0 | J18: PENDIENTE
A19: Gas protector para soldadura MIG/MAG | B19: COM-008 | C19: SOLDADURA | D19: m3 | I19: 0 | J19: PENDIENTE
A20: Tubo cuadrado de acero 30 × 30 mm | B20: COM-009 | C20: PERFIL | D20: m | I20: 0 | J20: PENDIENTE
A21: Tubo cuadrado de acero 40 × 40 mm | B21: COM-010 | C21: PERFIL | D21: m | I21: 0 | J21: PENDIENTE
A22: Ángulo de acero estructural | B22: COM-011 | C22: PERFIL | D22: m | I22: 0 | J22: PENDIENTE
... A42: Guante anticorte reutilizable | B42: COM-031 | C42: SEGURIDAD | D42: par | I42: 0 | J42: PENDIENTE

Sheet 03_DESPIECE
A1: Producto | B1: Componente | C1: Material | D1: Piezas por unidad | E1: Ancho pieza mm | F1: Alto pieza mm | G1: Longitud pieza m | H1: Área de chapa m² | I1: Masa kg / producto | J1: Costo S/ / producto | K1: Planchas 1.20×2.40 equivalentes / producto | L1: Costo disponible (1/0) | M1: Tipo de cálculo | N1: Naturaleza
A2: Minirack metálico con bandejas | B2: Parante vertical | C2: Tubo o perfil de acero (sección por definir) | D2: 4 | G2: 1.8 | I2: 10.8 | J2: 68.625 | L2: 1 | M2: PERFIL_LONGITUD | N2: ESTIMADO
A3: Minirack metálico con bandejas | B3: Larguero horizontal | C3: Tubo o perfil de acero (sección por definir) | D3: 8 | G3: 1.2 | I3: 14.4 | J3: 91.5 | L3: 1 | M3: PERFIL_LONGITUD | N3: ESTIMADO
A4: Minirack metálico con bandejas | B4: Refuerzo transversal | C4: Tubo o perfil de acero (sección por definir) | D4: 4 | G4: 0.6 | I4: 3.6 | J4: 22.875 | L4: 1 | M4: PERFIL_LONGITUD | N4: ESTIMADO
A5: Minirack metálico con bandejas | B5: Bandeja acero | C5: Plancha de acero laminado en caliente de 2 mm, 1.20 × 2.40 m | D5: 4 | H5: 0.72 | I5: 45.216 | J5: 334.20522 | K5: 1 | L5: 1 | M5: CHAPA_AREA | N5: ESTIMADO
A6: Minirack metálico con bandejas | B6: Cartela unión | C6: Plancha de acero laminado en caliente de 2 mm, 1.20 × 2.40 m | D6: 8 | H6: 0.025 | I6: 3.14 | J6: 23.208696 | K6: 0.069444444 | L6: 1 | M6: CHAPA_AREA | N6: ESTIMADO
A7: Minirack metálico con bandejas | B7: Tornillería sujeción | C7: Elementos de fijación metálica (tipo por desagregar) | D7: 24 | J7: 21.6 | L7: 1 | M7: UNIDAD | N7: ESTIMADO
A8: Minirack metálico con bandejas | B8: Tapa protectora | C8: Elementos de fijación metálica (tipo por desagregar) | D8: 4 | J8: 3.6 | L8: 1 | M8: UNIDAD | N8: ESTIMADO
A9: Estante reforzado modular | B9: Parante perfil | C9: Tubo o perfil de acero (sección por definir) | D9: 4 | G9: 2 | I9: 12 | J9: 76.25 | L9: 1 | M9: PERFIL_LONGITUD | N9: ESTIMADO
A10: Estante reforzado modular | B10: Travesaño frontal | C10: Tubo o perfil de acero (sección por definir) | D10: 8 | G10: 1 | I10: 12 | J10: 76.25 | L10: 1 | M10: PERFIL_LONGITUD | N10: ESTIMADO
A11: Estante reforzado modular | B11: Travesaño lateral | C11: Tubo o perfil de acero (sección por definir) | D11: 8 | G11: 0.5 | I11: 6 | J11: 38.125 | L11: 1 | M11: PERFIL_LONGITUD | N11: ESTIMADO
A12: Estante reforzado modular | B12: Bandeja reforzada | C12: Plancha de acero laminado en caliente de 2 mm, 1.20 × 2.40 m | D12: 5 | H12: 0.5 | I12: 39.25 | J12: 290.1087 | K12: 0.86805556 | L12: 1 | M12: CHAPA_AREA | N12: ESTIMADO
A13: Estante reforzado modular | B13: Cartela | C13: Plancha de acero laminado en caliente de 2 mm, 1.20 × 2.40 m | D13: 8 | H13: 0.035 | I13: 4.396 | J13: 32.492174 | K13: 0.097222222 | L13: 1 | M13: CHAPA_AREA | N13: ESTIMADO
A14: Estante reforzado modular | B14: Juego pernos | C14: Elementos de fijación metálica (tipo por desagregar) | D14: 28 | J14: 25.2 | L14: 1 | M14: UNIDAD | N14: ESTIMADO
A15: Góndola central comercial | B15: Columna doble | C15: Tubo o perfil de acero (sección por definir) | D15: 2 | G15: 1.65 | I15: 4.95 | J15: 31.453125 | L15: 1 | M15: PERFIL_LONGITUD | N15: ESTIMADO
A16: Góndola central comercial | B16: Base apoyo | C16: Lámina LAF o acero 1.0 mm (alternativa V4) | D16: 2 | H16: 0.3 | I16: 4.71 | J16: 34.813043 | K16: 0.20833333 | L16: 1 | M16: CHAPA_AREA | N16: ESTIMADO
A17: Góndola central comercial | B17: Panel trasero | C17: Lámina LAF o acero 1.0 mm (alternativa V4) | D17: 4 | H17: 0.56 | I17: 17.584 | J17: 129.9687 | K17: 0.77777778 | L17: 1 | M17: CHAPA_AREA | N17: ESTIMADO
A18: Góndola central comercial | B18: Estante de exposición | C18: Lámina LAF o acero 1.0 mm (alternativa V4) | D18: 8 | H18: 0.4 | I18: 25.12 | J18: 185.66957 | K18: 1.1111111 | L18: 1 | M18: CHAPA_AREA | N18: ESTIMADO
A19: Góndola central comercial | B19: Ménsula | C19: Lámina LAF o acero 1.0 mm (alternativa V4) | D19: 16 | H19: 0.04 | I19: 5.024 | J19: 37.133913 | K19: 0.22222222 | L19: 1 | M19: CHAPA_AREA | N19: ESTIMADO
A20: Góndola central comercial | B20: Zócalo frontal | C20: Lámina LAF o acero 1.0 mm (alternativa V4) | D20: 2 | H20: 0.12 | I20: 1.884 | J20: 13.925217 | K20: 0.083333333 | L20: 1 | M20: CHAPA_AREA | N20: ESTIMADO
A21: Góndola central comercial | B21: Pernos de ensamble | C21: Elementos de fijación metálica (tipo por desagregar) | D21: 36 | J21: 32.4 | L21: 1 | M21: UNIDAD | N21: ESTIMADO
A22: Góndola mural | B22: Montante mural | C22: Tubo o perfil de acero (sección por definir) | D22: 2 | G22: 1.9 | I22: 5.7 | J22: 36.21875 | L22: 1 | M22: PERFIL_LONGITUD | N22: ESTIMADO
A23: Góndola mural | B23: Panel de fondo | C23: Lámina LAF o acero 1.0 mm (alternativa V4) | D23: 3 | H23: 0.55 | I23: 12.9525 | J23: 95.73587 | K23: 0.57291667 | L23: 1 | M23: CHAPA_AREA | N23: ESTIMADO
A24: Góndola mural | B24: Bandeja | C24: Lámina LAF o acero 1.0 mm (alternativa V4) | D24: 5 | H24: 0.42 | I24: 16.485 | J24: 121.84565 | K24: 0.72916667 | L24: 1 | M24: CHAPA_AREA | N24: ESTIMADO
A25: Góndola mural | B25: Soporte bandeja | C25: Lámina LAF o acero 1.0 mm (alternativa V4) | D25: 10 | H25: 0.04 | I25: 3.14 | J25: 23.208696 | K25: 0.13888889 | L25: 1 | M25: CHAPA_AREA | N25: ESTIMADO
A26: Góndola mural | B26: Pie soporte | C26: Lámina LAF o acero 1.0 mm (alternativa V4) | D26: 2 | H26: 0.25 | I26: 3.925 | J26: 29.01087 | K26: 0.17361111 | L26: 1 | M26: CHAPA_AREA | N26: ESTIMADO
A27: Góndola mural | B27: Fijaciones | C27: Elementos de fijación metálica (tipo por desagregar) | D27: 26 | J27: 23.4 | L27: 1 | M27: UNIDAD | N27: ESTIMADO
A28: Locker de 4 puertas | B28: Panel lateral | C28: Lámina LAF o acero 1.5 mm (alternativa V4) | D28: 2 | H28: 0.95 | I28: 22.3725 | J28: 165.36196 | K28: 0.65972222 | L28: 1 | M28: CHAPA_AREA | N28: ESTIMADO
A29: Locker de 4 puertas | B29: Techo/base | C29: Lámina LAF o acero 1.5 mm (alternativa V4) | D29: 2 | H29: 0.35 | I29: 8.2425 | J29: 60.922826 | K29: 0.24305556 | L29: 1 | M29: CHAPA_AREA | N29: ESTIMADO
A30: Locker de 4 puertas | B30: Panel posterior | C30: Lámina LAF o acero 1.5 mm (alternativa V4) | D30: 1 | H30: 1.7 | I30: 20.0175 | J30: 147.95543 | K30: 0.59027778 | L30: 1 | M30: CHAPA_AREA | N30: ESTIMADO
A31: Locker de 4 puertas | B31: Puerta individual | C31: Lámina LAF o acero 1.5 mm (alternativa V4) | D31: 4 | H31: 0.37 | I31: 17.427 | J31: 128.80826 | K31: 0.51388889 | L31: 1 | M31: CHAPA_AREA | N31: ESTIMADO
A32: Locker de 4 puertas | B32: Separador interior | C32: Lámina LAF o acero 1.5 mm (alternativa V4) | D32: 3 | H32: 0.35 | I32: 12.36375 | J32: 91.384239 | K32: 0.36458333 | L32: 1 | M32: CHAPA_AREA | N32: ESTIMADO
A33: Locker de 4 puertas | B33: Bisagra | C33: Elementos de fijación metálica (tipo por desagregar) | D33: 8 | J33: 7.2 | L33: 1 | M33: UNIDAD | N33: ESTIMADO
A34: Locker de 4 puertas | B34: Cerradura | C34: Elementos de fijación metálica (tipo por desagregar) | D34: 4 | J34: 3.6 | L34: 1 | M34: UNIDAD | N34: ESTIMADO
A35: Locker de 6 puertas | B35: Costado externo | C35: Lámina LAF o acero 1.5 mm (alternativa V4) | D35: 2 | H35: 1.1 | I35: 25.905 | J35: 191.47174 | K35: 0.76388889 | L35: 1 | M35: CHAPA_AREA | N35: ESTIMADO
A36: Locker de 6 puertas | B36: Panel techo/base | C36: Lámina LAF o acero 1.5 mm (alternativa V4) | D36: 2 | H36: 0.48 | I36: 11.304 | J36: 83.551304 | K36: 0.33333333 | L36: 1 | M36: CHAPA_AREA | N36: ESTIMADO
A37: Locker de 6 puertas | B37: Fondo | C37: Lámina LAF o acero 1.5 mm (alternativa V4) | D37: 1 | H37: 1.8 | I37: 21.195 | J37: 156.6587 | K37: 0.625 | L37: 1 | M37: CHAPA_AREA | N37: ESTIMADO
A38: Locker de 6 puertas | B38: Puerta con rejilla | C38: Lámina LAF o acero 1.5 mm (alternativa V4) | D38: 6 | H38: 0.3 | I38: 21.195 | J38: 156.6587 | K38: 0.625 | L38: 1 | M38: CHAPA_AREA | N38: ESTIMADO
A39: Locker de 6 puertas | B39: Separador vertical | C39: Lámina LAF o acero 1.5 mm (alternativa V4) | D39: 2 | H39: 0.7 | I39: 16.485 | J39: 121.84565 | K39: 0.48611111 | L39: 1 | M39: CHAPA_AREA | N39: ESTIMADO
A40: Locker de 6 puertas | B40: Entrepiso | C40: Lámina LAF o acero 1.5 mm (alternativa V4) | D40: 4 | H40: 0.4 | I40: 18.84 | J40: 139.25217 | K40: 0.55555556 | L40: 1 | M40: CHAPA_AREA | N40: ESTIMADO
...

Sheet 04_MAQUINAS
A1: Equipo o recurso completo | B1: Clave interna | C1: Tipo técnico | D1: Tipo de recurso | E1: Cantidad de escenario | F1: Costo de uso S//h | G1: Potencia nominal kW (referencia) | H1: Factor de carga medio | I1: Grupo de operarios | J1: Máquina crítica (1/0) | K1: Operarios habilitados (simulado) | L1: Horas requeridas 2025 (calculado) | M1: Utilización anual 2025 | N1: Usado en rutas (1/0) | O1: Naturaleza
A2: Guillotina hidráulica para corte de planchas de acero | B2: CCH-01 | C2: Guillotina hidráulica de chapa, hasta 4 mm | D2: MAQUINA | E2: 1 | F2: 24 | G2: 5.5 | H2: 0.5 | I2: Corte | J2: 0 | K2: =SUMPRODUCT(('06B_HABILIDADES'!$B$1:$Q$1=A2)*('06B_HABILIDADES'!$B$2:$Q$26)) -> 6 | L2: =SUMIF('09_CARGA_ORDEN'!$E$2:$E$1153,A2,'09_CARGA_ORDEN'!$J$2:$J$1153) -> 658.53608 | M2: =IF(N(E2)=0,"",L2/(SUMPRODUCT((YEAR('07_CALENDARIO'!$A$2:$A$397)=p_anio_base)*'07_CALENDARIO'!$D$2:$D$397)*p_horas_productivas_dia*E2)) -> 0.31539084 | N2: =IF(COUNTIF('05_RUTAS'!$E$2:$E$407,A2)>0,1,0) -> 1 | O2: ESTIMADO
A3: Sierra de cinta para corte de tubos y perfiles | B3: CPR-01 | C3: Sierra de cinta para metal | D3: MAQUINA | E3: 1 | F3: 22 | G3: 0.75 | H3: 0.6 | I3: Corte | J3: 0 | K3: =SUMPRODUCT(('06B_HABILIDADES'!$B$1:$Q$1=A3)*('06B_HABILIDADES'!$B$2:$Q$26)) -> 3 | L3: =SUMIF('09_CARGA_ORDEN'!$E$2:$E$1153,A3,'09_CARGA_ORDEN'!$J$2:$J$1153) -> 331.64067 | M3: =IF(N(E3)=0,"",L3/(SUMPRODUCT((YEAR('07_CALENDARIO'!$A$2:$A$397)=p_anio_base)*'07_CALENDARIO'!$D$2:$D$397)*p_horas_productivas_dia*E3)) -> 0.15883174 | N3: =IF(COUNTIF('05_RUTAS'!$E$2:$E$407,A3)>0,1,0) -> 1 | O3: ESTIMADO
A4: Taladro de banco para perforación de acero | B4: PER-01 | C4: Taladro de banco industrial | D4: MAQUINA | E4: 1 | F4: 22 | G4: 0.55 | H4: 0.5 | I4: Perforación | J4: 0 | K4: =SUMPRODUCT(('06B_HABILIDADES'!$B$1:$Q$1=A4)*('06B_HABILIDADES'!$B$2:$Q$26)) -> 3 | L4: =SUMIF('09_CARGA_ORDEN'!$E$2:$E$1153,A4,'09_CARGA_ORDEN'!$J$2:$J$1153) -> 782.07 | M4: =IF(N(E4)=0,"",L4/(SUMPRODUCT((YEAR('07_CALENDARIO'!$A$2:$A$397)=p_anio_base)*'07_CALENDARIO'!$D$2:$D$397)*p_horas_productivas_dia*E4)) -> 0.3745546 | N4: =IF(COUNTIF('05_RUTAS'!$E$2:$E$407,A4)>0,1,0) -> 1 | O4: ESTIMADO
A5: Plegadora hidráulica de chapa metálica | B5: PLE-01 | C5: Plegadora hidráulica compacta | D5: MAQUINA | E5: 1 | F5: 28 | G5: 5.5 | H5: 0.45 | I5: Plegado | J5: 1 | K5: =SUMPRODUCT(('06B_HABILIDADES'!$B$1:$Q$1=A5)*('06B_HABILIDADES'!$B$2:$Q$26)) -> 3 | L5: =SUMIF('09_CARGA_ORDEN'!$E$2:$E$1153,A5,'09_CARGA_ORDEN'!$J$2:$J$1153) -> 1437.25 | M5: =IF(N(E5)=0,"",L5/(SUMPRODUCT((YEAR('07_CALENDARIO'!$A$2:$A$397)=p_anio_base)*'07_CALENDARIO'!$D$2:$D$397)*p_horas_productivas_dia*E5)) -> 0.68833812 | N5: =IF(COUNTIF('05_RUTAS'!$E$2:$E$407,A5)>0,1,0) -> 1 | O5: ESTIMADO
A6: Máquina de soldadura por arco MIG/MAG | B6: SOL-01 | C6: Soldadora inversora MIG/MAG | D6: MAQUINA | E6: 1 | F6: 32 | G6: 5 | H6: 0.35 | I6: Soldadura y armado | J6: 0 | K6: =SUMPRODUCT(('06B_HABILIDADES'!$B$1:$Q$1=A6)*('06B_HABILIDADES'!$B$2:$Q$26)) -> 5 | L6: =SUMIF('09_CARGA_ORDEN'!$E$2:$E$1153,A6,'09_CARGA_ORDEN'!$J$2:$J$1153) -> 403.58667 | M6: =IF(N(E6)=0,"",L6/(SUMPRODUCT((YEAR('07_CALENDARIO'!$A$2:$A$397)=p_anio_base)*'07_CALENDARIO'!$D$2:$D$397)*p_horas_productivas_dia*E6)) -> 0.19328863 | N6: =IF(COUNTIF('05_RUTAS'!$E$2:$E$407,A6)>0,1,0) -> 1 | O6: ESTIMADO
A7: Mesa de desbarbado/esmerilado | B7: DES-01 | C7: Mesa de desbarbado/esmerilado | D7: PUESTO_MANUAL | E7: 1 | F7: 21 | G7: 1.5 | H7: 0.5 | I7: Acabado | J7: 0 | K7: =SUMPRODUCT(('06B_HABILIDADES'!$B$1:$Q$1=A7)*('06B_HABILIDADES'!$B$2:$Q$26)) -> 5 | L7: =SUMIF('09_CARGA_ORDEN'!$E$2:$E$1153,A7,'09_CARGA_ORDEN'!$J$2:$J$1153) -> 508.225 | M7: =IF(N(E7)=0,"",L7/(SUMPRODUCT((YEAR('07_CALENDARIO'!$A$2:$A$397)=p_anio_base)*'07_CALENDARIO'!$D$2:$D$397)*p_horas_productivas_dia*E7)) -> 0.24340278 | N7: =IF(COUNTIF('05_RUTAS'!$E$2:$E$407,A7)>0,1,0) -> 1 | O7: ESTIMADO
A8: Zona de preparación superficial | B8: PRE-01 | C8: Zona de preparación superficial | D8: AREA | E8: 1 | F8: 19 | G8: 2.2 | H8: 0.4 | I8: Acabado | J8: 0 | K8: =SUMPRODUCT(('06B_HABILIDADES'!$B$1:$Q$1=A8)*('06B_HABILIDADES'!$B$2:$Q$26)) -> 4 | L8: =SUMIF('09_CARGA_ORDEN'!$E$2:$E$1153,A8,'09_CARGA_ORDEN'!$J$2:$J$1153) -> 437.39343 | M8: =IF(N(E8)=0,"",L8/(SUMPRODUCT((YEAR('07_CALENDARIO'!$A$2:$A$397)=p_anio_base)*'07_CALENDARIO'!$D$2:$D$397)*p_horas_productivas_dia*E8)) -> 0.20947961 | N8: =IF(COUNTIF('05_RUTAS'!$E$2:$E$407,A8)>0,1,0) -> 1 | O8: ESTIMADO
A9: Pistola manual de pintura electrostática en polvo | B9: PIN-01 | C9: Pistola manual de pintura electrostática en polvo | D9: EQUIPO_MANUAL | E9: 1 | F9: 32 | G9: 1.5 | H9: 0.7 | I9: Pintura y curado | J9: 0 | K9: =SUMPRODUCT(('06B_HABILIDADES'!$B$1:$Q$1=A9)*('06B_HABILIDADES'!$B$2:$Q$26)) -> 4 | L9: =SUMIF('09_CARGA_ORDEN'!$E$2:$E$1153,A9,'09_CARGA_ORDEN'!$J$2:$J$1153) -> 128.86083 | M9: =IF(N(E9)=0,"",L9/(SUMPRODUCT((YEAR('07_CALENDARIO'!$A$2:$A$397)=p_anio_base)*'07_CALENDARIO'!$D$2:$D$397)*p_horas_productivas_dia*E9)) -> 0.061714958 | N9: =IF(COUNTIF('05_RUTAS'!$E$2:$E$407,A9)>0,1,0) -> 1 | O9: ESTIMADO
A10: Mesa de armado | B10: ARM-01 | C10: Mesa de armado | D10: PUESTO_MANUAL | E10: 1 | F10: 19 | G10: 1 | H10: 0.3 | I10: Soldadura y armado | J10: 0 | K10: =SUMPRODUCT(('06B_HABILIDADES'!$B$1:$Q$1=A10)*('06B_HABILIDADES'!$B$2:$Q$26)) -> 5 | L10: =SUMIF('09_CARGA_ORDEN'!$E$2:$E$1153,A10,'09_CARGA_ORDEN'!$J$2:$J$1153) -> 775.975 | M10: =IF(N(E10)=0,"",L10/(SUMPRODUCT((YEAR('07_CALENDARIO'!$A$2:$A$397)=p_anio_base)*'07_CALENDARIO'!$D$2:$D$397)*p_horas_productivas_dia*E10)) -> 0.37163554 | N10: =IF(COUNTIF('05_RUTAS'!$E$2:$E$407,A10)>0,1,0) -> 1 | O10: ESTIMADO
A11: Área de inspección | B11: CAL-01 | C11: Área de inspección | D11: AREA | E11: 1 | F11: 20 | G11: 0.2 | H11: 0.5 | I11: Calidad y despacho | J11: 0 | K11: =SUMPRODUCT(('06B_HABILIDADES'!$B$1:$Q$1=A11)*('06B_HABILIDADES'!$B$2:$Q$26)) -> 5 | L11: =SUMIF('09_CARGA_ORDEN'!$E$2:$E$1153,A11,'09_CARGA_ORDEN'!$J$2:$J$1153) -> 56.082833 | M11: =IF(N(E11)=0,"",L11/(SUMPRODUCT((YEAR('07_CALENDARIO'!$A$2:$A$397)=p_anio_base)*'07_CALENDARIO'!$D$2:$D$397)*p_horas_productivas_dia*E11)) -> 0.026859595 | N11: =IF(COUNTIF('05_RUTAS'!$E$2:$E$407,A11)>0,1,0) -> 1 | O11: ESTIMADO
A12: Zona de protección y embalaje | B12: EMP-01 | C12: Zona de protección y embalaje | D12: AREA | E12: 1 | F12: 18 | G12: 0.3 | H12: 0.3 | I12: Calidad y despacho | J12: 0 | K12: =SUMPRODUCT(('06B_HABILIDADES'!$B$1:$Q$1=A12)*('06B_HABILIDADES'!$B$2:$Q$26)) -> 5 | L12: =SUMIF('09_CARGA_ORDEN'!$E$2:$E$1153,A12,'09_CARGA_ORDEN'!$J$2:$J$1153) -> 74.947 | M12: =IF(N(E12)=0,"",L12/(SUMPRODUCT((YEAR('07_CALENDARIO'!$A$2:$A$397)=p_anio_base)*'07_CALENDARIO'!$D$2:$D$397)*p_horas_productivas_dia*E12)) -> 0.035894157 | N12: =IF(COUNTIF('05_RUTAS'!$E$2:$E$407,A12)>0,1,0) -> 1 | O12: ESTIMADO
A13: Segundo taladro (alternativo) | B13: PER-02 | C13: Segundo taladro (alternativo) | D13: MAQUINA | E13: 1 | F13: 22 | G13: 0.75 | H13: 0.5 | I13: Perforación | J13: 0 | K13: =SUMPRODUCT(('06B_HABILIDADES'!$B$1:$Q$1=A13)*('06B_HABILIDADES'!$B$2:$Q$26)) -> 3 | L13: =SUMIF('09_CARGA_ORDEN'!$E$2:$E$1153,A13,'09_CARGA_ORDEN'!$J$2:$J$1153) -> 0 | M13: =IF(N(E13)=0,"",L13/(SUMPRODUCT((YEAR('07_CALENDARIO'!$A$2:$A$397)=p_anio_base)*'07_CALENDARIO'!$D$2:$D$397)*p_horas_productivas_dia*E13)) -> 0 | N13: =IF(COUNTIF('05_RUTAS'!$E$2:$E$407,A13)>0,1,0) -> 1 | O13: ESTIMADO
A14: Segunda estación soldadura (alternativa) | B14: SOL-02 | C14: Segunda estación soldadura (alternativa) | D14: MAQUINA | E14: 1 | F14: 32 | G14: 5 | H14: 0.35 | I14: Soldadura y armado | J14: 0 | K14: =SUMPRODUCT(('06B_HABILIDADES'!$B$1:$Q$1=A14)*('06B_HABILIDADES'!$B$2:$Q$26)) -> 5 | L14: =SUMIF('09_CARGA_ORDEN'!$E$2:$E$1153,A14,'09_CARGA_ORDEN'!$J$2:$J$1153) -> 0 | M14: =IF(N(E14)=0,"",L14/(SUMPRODUCT((YEAR('07_CALENDARIO'!$A$2:$A$397)=p_anio_base)*'07_CALENDARIO'!$D$2:$D$397)*p_horas_productivas_dia*E14)) -> 0 | N14: =IF(COUNTIF('05_RUTAS'!$E$2:$E$407,A14)>0,1,0) -> 1 | O14: ESTIMADO
A15: Proveedor de pintura externo | B15: PIN-EXT | C15: Proveedor de pintura externo | D15: EXTERNO | E15: 0 | G15: 0 | H15: 0 | I15: No aplica | J15: 0 | K15: =SUMPRODUCT(('06B_HABILIDADES'!$B$1:$Q$1=A15)*('06B_HABILIDADES'!$B$2:$Q$26)) -> 0 | L15: =SUMIF('09_CARGA_ORDEN'!$E$2:$E$1153,A15,'09_CARGA_ORDEN'!$J$2:$J$1153) -> 0 | M15: =IF(N(E15)=0,"",L15/(SUMPRODUCT((YEAR('07_CALENDARIO'!$A$2:$A$397)=p_anio_base)*'07_CALENDARIO'!$D$2:$D$397)*p_horas_productivas_dia*E15)) | N15: =IF(COUNTIF('05_RUTAS'!$E$2:$E$407,A15)>0,1,0) -> 0 | O15: ESTIMADO
A16: Horno de curado de pintura electrostática por lotes | B16: HOR-01 | C16: Horno de curado de pintura electrostática por lotes | D16: MAQUINA | E16: 1 | F16: 26 | G16: 24 | H16: 0.6 | I16: Pintura y curado | J16: 0 | K16: =SUMPRODUCT(('06B_HABILIDADES'!$B$1:$Q$1=A16)*('06B_HABILIDADES'!$B$2:$Q$26)) -> 2 | L16: =SUMIF('09_CARGA_ORDEN'!$E$2:$E$1153,A16,'09_CARGA_ORDEN'!$J$2:$J$1153) -> 94.5 | M16: =IF(N(E16)=0,"",L16/(SUMPRODUCT((YEAR('07_CALENDARIO'!$A$2:$A$397)=p_anio_base)*'07_CALENDARIO'!$D$2:$D$397)*p_horas_productivas_dia*E16)) -> 0.045258621 | N16: =IF(COUNTIF('05_RUTAS'!$E$2:$E$407,A16)>0,1,0) -> 1 | O16: ESTIMADO
A17: Manipulación y enfriamiento de piezas | B17: MAN-01 | C17: Manipulación y enfriamiento de piezas | D17: PUESTO_MANUAL | E17: 1 | F17: 16 | G17: 0.5 | H17: 0.5 | I17: Pintura y curado | J17: 0 | K17: =SUMPRODUCT(('06B_HABILIDADES'!$B$1:$Q$1=A17)*('06B_HABILIDADES'!$B$2:$Q$26)) -> 2 | L17: =SUMIF('09_CARGA_ORDEN'!$E$2:$E$1153,A17,'09_CARGA_ORDEN'!$J$2:$J$1153) -> 52.655167 | M17: =IF(N(E17)=0,"",L17/(SUMPRODUCT((YEAR('07_CALENDARIO'!$A$2:$A$397)=p_anio_base)*'07_CALENDARIO'!$D$2:$D$397)*p_horas_productivas_dia*E17)) -> 0.025217992 | N17: =IF(COUNTIF('05_RUTAS'!$E$2:$E$407,A17)>0,1,0) -> 1 | O17: ESTIMADO
A18: Sala acondicionada para pintura electrostática | B18: SAL-PIN | C18: Sala acondicionada para pintura electrostática | D18: AREA | E18: 1 | G18: 3 | H18: 0.5 | I18: Pintura y curado | J18: 0 | K18: =SUMPRODUCT(('06B_HABILIDADES'!$B$1:$Q$1=A18)*('06B_HABILIDADES'!$B$2:$Q$26)) -> 4 | L18: =SUMIF('09_CARGA_ORDEN'!$E$2:$E$1153,A18,'09_CARGA_ORDEN'!$J$2:$J$1153) -> 0 | M18: =IF(N(E18)=0,"",L18/(SUMPRODUCT((YEAR('07_CALENDARIO'!$A$2:$A$397)=p_anio_base)*'07_CALENDARIO'!$D$2:$D$397)*p_horas_productivas_dia*E18)) -> 0 | N18: =IF(COUNTIF('05_RUTAS'!$E$2:$E$407,A18)>0,1,0) -> 0 | O18: ESTIMADO

Sheet 05_RUTAS
A1: Producto | B1: Familia | C1: Paso | D1: Operación | E1: Equipo principal | F1: Min fijos por lote | G1: Minutos por unidad | H1: Precedencia | I1: Tratamiento del tiempo | J1: Min ciclo horno (incluidos) | K1: Origen de duración | L1: Equipo válido (1/0) | M1: Naturaleza
A2: Minirack metálico con bandejas | B2: Racks industriales | C2: 1 | D2: Corte de planchas de acero | E2: Guillotina hidráulica para corte de planchas de acero | F2: 8 | G2: 34.62 | H2: Inicio | I2: POR_UNIDAD | J2: 0 | K2: VALOR HEREDADO SIN CRONOMETRAJE | L2: =IF(COUNTIF('04_MAQUINAS'!$A$2:$A$18,E2)>0,1,0) -> 1 | M2: ESTIMADO
A3: Minirack metálico con bandejas | B3: Racks industriales | C3: 2 | D3: Corte de tubos y perfiles | E3: Sierra de cinta para corte de tubos y perfiles | F3: 8 | G3: 43.52 | H3: 1 | I3: POR_UNIDAD | J3: 0 | K3: VALOR HEREDADO SIN CRONOMETRAJE | L3: =IF(COUNTIF('04_MAQUINAS'!$A$2:$A$18,E3)>0,1,0) -> 1 | M3: ESTIMADO
A4: Minirack metálico con bandejas | B4: Racks industriales | C4: 3 | D4: Perforación | E4: Taladro de banco para perforación de acero | F4: 10 | G4: 63.2 | H4: 2 | I4: POR_UNIDAD | J4: 0 | K4: VALOR HEREDADO SIN CRONOMETRAJE | L4: =IF(COUNTIF('04_MAQUINAS'!$A$2:$A$18,E4)>0,1,0) -> 1 | M4: ESTIMADO
A5: Minirack metálico con bandejas | B5: Racks industriales | C5: 4 | D5: Plegado | E5: Plegadora hidráulica de chapa metálica | F5: 12 | G5: 60 | H5: 3 | I5: POR_UNIDAD | J5: 0 | K5: VALOR HEREDADO SIN CRONOMETRAJE | L5: =IF(COUNTIF('04_MAQUINAS'!$A$2:$A$18,E5)>0,1,0) -> 1 | M5: ESTIMADO
A6: Minirack metálico con bandejas | B6: Racks industriales | C6: 5 | D6: Soldadura | E6: Máquina de soldadura por arco MIG/MAG | F6: 10 | G6: 78.4 | H6: 4 | I6: POR_UNIDAD | J6: 0 | K6: VALOR HEREDADO SIN CRONOMETRAJE | L6: =IF(COUNTIF('04_MAQUINAS'!$A$2:$A$18,E6)>0,1,0) -> 1 | M6: ESTIMADO
A7: Minirack metálico con bandejas | B7: Racks industriales | C7: 6 | D7: Desbarbado | E7: Mesa de desbarbado/esmerilado | F7: 3 | G7: 42 | H7: 5 | I7: POR_UNIDAD | J7: 0 | K7: VALOR HEREDADO SIN CRONOMETRAJE | L7: =IF(COUNTIF('04_MAQUINAS'!$A$2:$A$18,E7)>0,1,0) -> 1 | M7: ESTIMADO
A8: Minirack metálico con bandejas | B8: Racks industriales | C8: 7 | D8: Preparación superficial | E8: Zona de preparación superficial | F8: 6 | G8: 29.7248 | H8: 6 | I8: POR_UNIDAD | J8: 0 | K8: VALOR HEREDADO SIN CRONOMETRAJE | L8: =IF(COUNTIF('04_MAQUINAS'!$A$2:$A$18,E8)>0,1,0) -> 1 | M8: ESTIMADO
A9: Minirack metálico con bandejas | B9: Racks industriales | C9: 8 | D9: Aplicación electrostática de polvo | E9: Pistola manual de pintura electrostática en polvo | F9: 12 | G9: 8.02 | H9: 7 | I9: POR_UNIDAD | J9: 0 | K9: HIPOTESIS TECNICA | L9: =IF(COUNTIF('04_MAQUINAS'!$A$2:$A$18,E9)>0,1,0) -> 1 | M9: ESTIMADO
A10: Minirack metálico con bandejas | B10: Racks industriales | C10: 9 | D10: Curado térmico en horno | E10: Horno de curado de pintura electrostática por lotes | F10: 45 | G10: 0 | H10: 8 | I10: POR_LOTE | J10: 40 | K10: HIPOTESIS TECNICA | L10: =IF(COUNTIF('04_MAQUINAS'!$A$2:$A$18,E10)>0,1,0) -> 1 | M10: ESTIMADO
A11: Minirack metálico con bandejas | B11: Racks industriales | C11: 10 | D11: Colgado, traslado y enfriamiento | E11: Manipulación y enfriamiento de piezas | F11: 8 | G11: 2.69 | H11: 9 | I11: POR_UNIDAD | J11: 0 | K11: HIPOTESIS TECNICA | L11: =IF(COUNTIF('04_MAQUINAS'!$A$2:$A$18,E11)>0,1,0) -> 1 | M11: ESTIMADO
A12: Minirack metálico con bandejas | B12: Racks industriales | C12: 11 | D12: Ensamblaje | E12: Mesa de armado | F12: 6 | G12: 60 | H12: 10 | I12: POR_UNIDAD | J12: 0 | K12: VALOR HEREDADO SIN CRONOMETRAJE | L12: =IF(COUNTIF('04_MAQUINAS'!$A$2:$A$18,E12)>0,1,0) -> 1 | M12: ESTIMADO
A13: Minirack metálico con bandejas | B13: Racks industriales | C13: 12 | D13: Inspección de calidad | E13: Área de inspección | F13: 2 | G13: 3.86 | H13: 11 | I13: POR_UNIDAD | J13: 0 | K13: HIPOTESIS TECNICA | L13: =IF(COUNTIF('04_MAQUINAS'!$A$2:$A$18,E13)>0,1,0) -> 1 | M13: ESTIMADO
A14: Minirack metálico con bandejas | B14: Racks industriales | C14: 13 | D14: Embalaje | E14: Zona de protección y embalaje | F14: 2 | G14: 5.3 | H14: 12 | I14: POR_UNIDAD | J14: 0 | K14: HIPOTESIS TECNICA | L14: =IF(COUNTIF('04_MAQUINAS'!$A$2:$A$18,E14)>0,1,0) -> 1 | M14: ESTIMADO
A15: Estante reforzado modular | B15: Racks industriales | C15: 1 | D15: Corte de planchas de acero | E15: Guillotina hidráulica para corte de planchas de acero | F15: 8 | G15: 36.67 | H15: Inicio | I15: POR_UNIDAD | J15: 0 | K15: VALOR HEREDADO SIN CRONOMETRAJE | L15: =IF(COUNTIF('04_MAQUINAS'!$A$2:$A$18,E15)>0,1,0) -> 1 | M15: ESTIMADO
A16: Estante reforzado modular | B16: Racks industriales | C16: 2 | D16: Corte de tubos y perfiles | E16: Sierra de cinta para corte de tubos y perfiles | F16: 8 | G16: 52 | H16: 1 | I16: POR_UNIDAD | J16: 0 | K16: VALOR HEREDADO SIN CRONOMETRAJE | L16: =IF(COUNTIF('04_MAQUINAS'!$A$2:$A$18,E16)>0,1,0) -> 1 | M16: ESTIMADO
A17: Estante reforzado modular | B17: Racks industriales | C17: 3 | D17: Perforación | E17: Taladro de banco para perforación de acero | F17: 10 | G17: 82.1 | H17: 2 | I17: POR_UNIDAD | J17: 0 | K17: VALOR HEREDADO SIN CRONOMETRAJE | L17: =IF(COUNTIF('04_MAQUINAS'!$A$2:$A$18,E17)>0,1,0) -> 1 | M17: ESTIMADO
A18: Estante reforzado modular | B18: Racks industriales | C18: 4 | D18: Plegado | E18: Plegadora hidráulica de chapa metálica | F18: 12 | G18: 69 | H18: 3 | I18: POR_UNIDAD | J18: 0 | K18: VALOR HEREDADO SIN CRONOMETRAJE | L18: =IF(COUNTIF('04_MAQUINAS'!$A$2:$A$18,E18)>0,1,0) -> 1 | M18: ESTIMADO
A19: Estante reforzado modular | B19: Racks industriales | C19: 5 | D19: Soldadura | E19: Máquina de soldadura por arco MIG/MAG | F19: 10 | G19: 78.4 | H19: 4 | I19: POR_UNIDAD | J19: 0 | K19: VALOR HEREDADO SIN CRONOMETRAJE | L19: =IF(COUNTIF('04_MAQUINAS'!$A$2:$A$18,E19)>0,1,0) -> 1 | M19: ESTIMADO
A20: Estante reforzado modular | B20: Racks industriales | C20: 6 | D20: Desbarbado | E20: Mesa de desbarbado/esmerilado | F20: 3 | G20: 49.5 | H20: 5 | I20: POR_UNIDAD | J20: 0 | K20: VALOR HEREDADO SIN CRONOMETRAJE | L20: =IF(COUNTIF('04_MAQUINAS'!$A$2:$A$18,E20)>0,1,0) -> 1 | M20: ESTIMADO
A21: Estante reforzado modular | B21: Racks industriales | C21: 7 | D21: Preparación superficial | E21: Zona de preparación superficial | F21: 6 | G21: 32.064 | H21: 6 | I21: POR_UNIDAD | J21: 0 | K21: VALOR HEREDADO SIN CRONOMETRAJE | L21: =IF(COUNTIF('04_MAQUINAS'!$A$2:$A$18,E21)>0,1,0) -> 1 | M21: ESTIMADO
A22: Estante reforzado modular | B22: Racks industriales | C22: 8 | D22: Aplicación electrostática de polvo | E22: Pistola manual de pintura electrostática en polvo | F22: 12 | G22: 8.02 | H22: 7 | I22: POR_UNIDAD | J22: 0 | K22: HIPOTESIS TECNICA | L22: =IF(COUNTIF('04_MAQUINAS'!$A$2:$A$18,E22)>0,1,0) -> 1 | M22: ESTIMADO
A23: Estante reforzado modular | B23: Racks industriales | C23: 9 | D23: Curado térmico en horno | E23: Horno de curado de pintura electrostática por lotes | F23: 45 | G23: 0 | H23: 8 | I23: POR_LOTE | J23: 40 | K23: HIPOTESIS TECNICA | L23: =IF(COUNTIF('04_MAQUINAS'!$A$2:$A$18,E23)>0,1,0) -> 1 | M23: ESTIMADO
A24: Estante reforzado modular | B24: Racks industriales | C24: 10 | D24: Colgado, traslado y enfriamiento | E24: Manipulación y enfriamiento de piezas | F24: 8 | G24: 2.69 | H24: 9 | I24: POR_UNIDAD | J24: 0 | K24: HIPOTESIS TECNICA | L24: =IF(COUNTIF('04_MAQUINAS'!$A$2:$A$18,E24)>0,1,0) -> 1 | M24: ESTIMADO
A25: Estante reforzado modular | B25: Racks industriales | C25: 11 | D25: Ensamblaje | E25: Mesa de armado | F25: 6 | G25: 62.25 | H25: 10 | I25: POR_UNIDAD | J25: 0 | K25: VALOR HEREDADO SIN CRONOMETRAJE | L25: =IF(COUNTIF('04_MAQUINAS'!$A$2:$A$18,E25)>0,1,0) -> 1 | M25: ESTIMADO
A26: Estante reforzado modular | B26: Racks industriales | C26: 12 | D26: Inspección de calidad | E26: Área de inspección | F26: 2 | G26: 3.86 | H26: 11 | I26: POR_UNIDAD | J26: 0 | K26: HIPOTESIS TECNICA | L26: =IF(COUNTIF('04_MAQUINAS'!$A$2:$A$18,E26)>0,1,0) -> 1 | M26: ESTIMADO
A27: Estante reforzado modular | B27: Racks industriales | C27: 13 | D27: Embalaje | E27: Zona de protección y embalaje | F27: 2 | G27: 5.3 | H27: 12 | I27: POR_UNIDAD | J27: 0 | K27: HIPOTESIS TECNICA | L27: =IF(COUNTIF('04_MAQUINAS'!$A$2:$A$18,E27)>0,1,0) -> 1 | M27: ESTIMADO
A28: Góndola central comercial | B28: Góndolas comerciales | C28: 1 | D28: Corte de planchas de acero | E28: Guillotina hidráulica para corte de planchas de acero | F28: 8 | G28: 90.38 | H28: Inicio | I28: POR_UNIDAD | J28: 0 | K28: VALOR HEREDADO SIN CRONOMETRAJE | L28: =IF(COUNTIF('04_MAQUINAS'!$A$2:$A$18,E28)>0,1,0) -> 1 | M28: ESTIMADO
A29: Góndola central comercial | B29: Góndolas comerciales | C29: 2 | D29: Corte de tubos y perfiles | E29: Sierra de cinta para corte de tubos y perfiles | F29: 8 | G29: 5.98 | H29: 1 | I29: POR_UNIDAD | J29: 0 | K29: VALOR HEREDADO SIN CRONOMETRAJE | L29: =IF(COUNTIF('04_MAQUINAS'!$A$2:$A$18,E29)>0,1,0) -> 1 | M29: ESTIMADO
A30: Góndola central comercial | B30: Góndolas comerciales | C30: 3 | D30: Perforación | E30: Taladro de banco para perforación de acero | F30: 10 | G30: 97 | H30: 2 | I30: POR_UNIDAD | J30: 0 | K30: VALOR HEREDADO SIN CRONOMETRAJE | L30: =IF(COUNTIF('04_MAQUINAS'!$A$2:$A$18,E30)>0,1,0) -> 1 | M30: ESTIMADO
A31: Góndola central comercial | B31: Góndolas comerciales | C31: 4 | D31: Plegado | E31: Plegadora hidráulica de chapa metálica | F31: 12 | G31: 196 | H31: 3 | I31: POR_UNIDAD | J31: 0 | K31: VALOR HEREDADO SIN CRONOMETRAJE | L31: =IF(COUNTIF('04_MAQUINAS'!$A$2:$A$18,E31)>0,1,0) -> 1 | M31: ESTIMADO
A32: Góndola central comercial | B32: Góndolas comerciales | C32: 5 | D32: Desbarbado | E32: Mesa de desbarbado/esmerilado | F32: 3 | G32: 51 | H32: 4 | I32: POR_UNIDAD | J32: 0 | K32: VALOR HEREDADO SIN CRONOMETRAJE | L32: =IF(COUNTIF('04_MAQUINAS'!$A$2:$A$18,E32)>0,1,0) -> 1 | M32: ESTIMADO
A33: Góndola central comercial | B33: Góndolas comerciales | C33: 6 | D33: Preparación superficial | E33: Zona de preparación superficial | F33: 6 | G33: 40.5152 | H33: 5 | I33: POR_UNIDAD | J33: 0 | K33: VALOR HEREDADO SIN CRONOMETRAJE | L33: =IF(COUNTIF('04_MAQUINAS'!$A$2:$A$18,E33)>0,1,0) -> 1 | M33: ESTIMADO
A34: Góndola central comercial | B34: Góndolas comerciales | C34: 7 | D34: Aplicación electrostática de polvo | E34: Pistola manual de pintura electrostática en polvo | F34: 12 | G34: 7.76 | H34: 6 | I34: POR_UNIDAD | J34: 0 | K34: HIPOTESIS TECNICA | L34: =IF(COUNTIF('04_MAQUINAS'!$A$2:$A$18,E34)>0,1,0) -> 1 | M34: ESTIMADO
A35: Góndola central comercial | B35: Góndolas comerciales | C35: 8 | D35: Curado térmico en horno | E35: Horno de curado de pintura electrostática por lotes | F35: 45 | G35: 0 | H35: 7 | I35: POR_LOTE | J35: 40 | K35: HIPOTESIS TECNICA | L35: =IF(COUNTIF('04_MAQUINAS'!$A$2:$A$18,E35)>0,1,0) -> 1 | M35: ESTIMADO
A36: Góndola central comercial | B36: Góndolas comerciales | C36: 9 | D36: Colgado, traslado y enfriamiento | E36: Manipulación y enfriamiento de piezas | F36: 8 | G36: 2.63 | H36: 8 | I36: POR_UNIDAD | J36: 0 | K36: HIPOTESIS TECNICA | L36: =IF(COUNTIF('04_MAQUINAS'!$A$2:$A$18,E36)>0,1,0) -> 1 | M36: ESTIMADO
A37: Góndola central comercial | B37: Góndolas comerciales | C37: 10 | D37: Ensamblaje | E37: Mesa de armado | F37: 6 | G37: 69 | H37: 9 | I37: POR_UNIDAD | J37: 0 | K37: VALOR HEREDADO SIN CRONOMETRAJE | L37: =IF(COUNTIF('04_MAQUINAS'!$A$2:$A$18,E37)>0,1,0) -> 1 | M37: ESTIMADO
A38: Góndola central comercial | B38: Góndolas comerciales | C38: 11 | D38: Inspección de calidad | E38: Área de inspección | F38: 2 | G38: 3.79 | H38: 10 | I38: POR_UNIDAD | J38: 0 | K38: HIPOTESIS TECNICA | L38: =IF(COUNTIF('04_MAQUINAS'!$A$2:$A$18,E38)>0,1,0) -> 1 | M38: ESTIMADO
A39: Góndola central comercial | B39: Góndolas comerciales | C39: 12 | D39: Embalaje | E39: Zona de protección y embalaje | F39: 2 | G39: 5.18 | H39: 11 | I39: POR_UNIDAD | J39: 0 | K39: HIPOTESIS TECNICA | L39: =IF(COUNTIF('04_MAQUINAS'!$A$2:$A$18,E39)>0,1,0) -> 1 | M39: ESTIMADO
A40: Góndola mural | B40: Góndolas comerciales | C40: 1 | D40: Corte de planchas de acero | E40: Guillotina hidráulica para corte de planchas de acero | F40: 8 | G40: 56.975 | H40: Inicio | I40: POR_UNIDAD | J40: 0 | K40: VALOR HEREDADO SIN CRONOMETRAJE | L40: =IF(COUNTIF('04_MAQUINAS'!$A$2:$A$18,E40)>0,1,0) -> 1 | M40: ESTIMADO
...

Sheet 06B_HABILIDADES
A1: Operario (seudónimo) | B1: Guillotina hidráulica para corte de planchas de acero | C1: Sierra de cinta para corte de tubos y perfiles | D1: Taladro de banco para perforación de acero | E1: Plegadora hidráulica de chapa metálica | F1: Máquina de soldadura por arco MIG/MAG | G1: Mesa de desbarbado/esmerilado | H1: Zona de preparación superficial | I1: Pistola manual de pintura electrostática en polvo | J1: Mesa de armado | K1: Área de inspección | L1: Zona de protección y embalaje | M1: Segundo taladro (alternativo) | N1: Segunda estación soldadura (alternativa) | O1: Horno de curado de pintura electrostática por lotes | P1: Manipulación y enfriamiento de piezas | Q1: Sala acondicionada para pintura electrostática | R1: Naturaleza
A2: OP-01 | B2: 1 | C2: 1 | D2: 0 | E2: 0 | F2: 0 | G2: 0 | H2: 0 | I2: 0 | J2: 0 | K2: 0 | L2: 0 | M2: 0 | N2: 0 | O2: 0 | P2: 0 | Q2: 0 | R2: SIMULADO
A3: OP-02 | B3: 1 | C3: 1 | D3: 0 | E3: 0 | F3: 0 | G3: 0 | H3: 0 | I3: 0 | J3: 0 | K3: 0 | L3: 0 | M3: 0 | N3: 0 | O3: 0 | P3: 0 | Q3: 0 | R3: SIMULADO
A4: OP-03 | B4: 0 | C4: 0 | D4: 1 | E4: 0 | F4: 0 | G4: 0 | H4: 0 | I4: 0 | J4: 0 | K4: 0 | L4: 0 | M4: 1 | N4: 0 | O4: 0 | P4: 0 | Q4: 0 | R4: SIMULADO
A5: OP-04 | B5: 1 | C5: 0 | D5: 0 | E5: 1 | F5: 0 | G5: 0 | H5: 0 | I5: 0 | J5: 0 | K5: 0 | L5: 0 | M5: 0 | N5: 0 | O5: 0 | P5: 0 | Q5: 0 | R5: SIMULADO
A6: OP-05 | B6: 0 | C6: 0 | D6: 0 | E6: 0 | F6: 1 | G6: 1 | H6: 0 | I6: 0 | J6: 0 | K6: 0 | L6: 0 | M6: 0 | N6: 1 | O6: 0 | P6: 0 | Q6: 0 | R6: SIMULADO
A7: OP-06 | B7: 0 | C7: 0 | D7: 0 | E7: 0 | F7: 1 | G7: 1 | H7: 0 | I7: 0 | J7: 0 | K7: 0 | L7: 0 | M7: 0 | N7: 1 | O7: 0 | P7: 0 | Q7: 0 | R7: SIMULADO
A8: OP-07 | B8: 0 | C8: 0 | D8: 0 | E8: 0 | F8: 0 | G8: 0 | H8: 1 | I8: 1 | J8: 0 | K8: 0 | L8: 0 | M8: 0 | N8: 0 | O8: 0 | P8: 0 | Q8: 1 | R8: SIMULADO
A9: OP-08 | B9: 0 | C9: 0 | D9: 0 | E9: 0 | F9: 0 | G9: 0 | H9: 1 | I9: 1 | J9: 0 | K9: 0 | L9: 0 | M9: 0 | N9: 0 | O9: 0 | P9: 0 | Q9: 1 | R9: SIMULADO
A10: OP-09 | B10: 0 | C10: 0 | D10: 0 | E10: 0 | F10: 0 | G10: 0 | H10: 0 | I10: 0 | J10: 1 | K10: 1 | L10: 1 | M10: 0 | N10: 0 | O10: 0 | P10: 0 | Q10: 0 | R10: SIMULADO
A11: OP-10 | B11: 0 | C11: 0 | D11: 0 | E11: 0 | F11: 0 | G11: 0 | H11: 0 | I11: 0 | J11: 1 | K11: 1 | L11: 1 | M11: 0 | N11: 0 | O11: 0 | P11: 0 | Q11: 0 | R11: SIMULADO
A12: OP-11 | B12: 0 | C12: 0 | D12: 0 | E12: 0 | F12: 0 | G12: 0 | H12: 0 | I12: 0 | J12: 1 | K12: 1 | L12: 1 | M12: 0 | N12: 0 | O12: 0 | P12: 0 | Q12: 0 | R12: SIMULADO
A13: OP-12 | B13: 0 | C13: 0 | D13: 1 | E13: 0 | F13: 0 | G13: 0 | H13: 0 | I13: 0 | J13: 0 | K13: 0 | L13: 0 | M13: 1 | N13: 0 | O13: 0 | P13: 0 | Q13: 0 | R13: SIMULADO
... A26: OP-25 | B26: 0 | C26: 0 | D26: 1 | E26: 0 | F26: 0 | G26: 0 | H26: 0 | I26: 0 | J26: 0 | K26: 0 | L26: 0 | M26: 1 | N26: 0 | O26: 0 | P26: 0 | Q26: 0 | R26: SIMULADO

Sheet 06_OPERARIOS
A1: Operario (seudónimo) | B1: Especialidad (simulada) | C1: Turnos | D1: Horas netas / día | E1: Naturaleza
A2: OP-01 | B2: Corte | C2: 1 | D2: 8 | E2: REAL (cantidad y jornada); especialidad SIMULADA
A3: OP-02 | B3: Corte | C3: 1 | D3: 8 | E3: REAL (cantidad y jornada); especialidad SIMULADA
A4: OP-03 | B4: Perforación | C4: 1 | D4: 8 | E4: REAL (cantidad y jornada); especialidad SIMULADA
A5: OP-04 | B5: Plegado | C5: 1 | D5: 8 | E5: REAL (cantidad y jornada); especialidad SIMULADA
A6: OP-05 | B6: Soldadura | C6: 1 | D6: 8 | E6: REAL (cantidad y jornada); especialidad SIMULADA
A7: OP-06 | B7: Desbarbado | C7: 1 | D7: 8 | E7: REAL (cantidad y jornada); especialidad SIMULADA
A8: OP-07 | B8: Preparación superficial | C8: 1 | D8: 8 | E8: REAL (cantidad y jornada); especialidad SIMULADA
A9: OP-08 | B9: Pintura | C9: 1 | D9: 8 | E9: REAL (cantidad y jornada); especialidad SIMULADA
A10: OP-09 | B10: Armado | C10: 1 | D10: 8 | E10: REAL (cantidad y jornada); especialidad SIMULADA
A11: OP-10 | B11: Inspección | C11: 1 | D11: 8 | E11: REAL (cantidad y jornada); especialidad SIMULADA
A12: OP-11 | B12: Embalaje | C12: 1 | D12: 8 | E12: REAL (cantidad y jornada); especialidad SIMULADA
A13: OP-12 | B13: Perforación | C13: 1 | D13: 8 | E13: REAL (cantidad y jornada); especialidad SIMULADA
... A26: OP-25 | B26: Perforación | C26: 1 | D26: 8 | E26: REAL (cantidad y jornada); especialidad SIMULADA

Sheet 07_CALENDARIO
A1: Fecha | B1: Productivo (1/0) | C1: Feriado nacional Perú | D1: Productivo efectivo (1/0) | E1: Naturaleza
A2: 45658 | B2: 1 | C2: Año Nuevo | D2: =IF(AND(p_aplicar_feriados=1,C2<>""),0,B2) -> 1 | E2: ESTIMADO
A3: 45659 | B3: 1 | D3: =IF(AND(p_aplicar_feriados=1,C3<>""),0,B3) -> 1 | E3: ESTIMADO
A4: 45660 | B4: 1 | D4: =IF(AND(p_aplicar_feriados=1,C4<>""),0,B4) -> 1 | E4: ESTIMADO
A5: 45661 | B5: 0 | D5: =IF(AND(p_aplicar_feriados=1,C5<>""),0,B5) -> 0 | E5: ESTIMADO
A6: 45662 | B6: 0 | D6: =IF(AND(p_aplicar_feriados=1,C6<>""),0,B6) -> 0 | E6: ESTIMADO
A7: 45663 | B7: 1 | D7: =IF(AND(p_aplicar_feriados=1,C7<>""),0,B7) -> 1 | E7: ESTIMADO
A8: 45664 | B8: 1 | D8: =IF(AND(p_aplicar_feriados=1,C8<>""),0,B8) -> 1 | E8: ESTIMADO
A9: 45665 | B9: 1 | D9: =IF(AND(p_aplicar_feriados=1,C9<>""),0,B9) -> 1 | E9: ESTIMADO
A10: 45666 | B10: 1 | D10: =IF(AND(p_aplicar_feriados=1,C10<>""),0,B10) -> 1 | E10: ESTIMADO
A11: 45667 | B11: 1 | D11: =IF(AND(p_aplicar_feriados=1,C11<>""),0,B11) -> 1 | E11: ESTIMADO
A12: 45668 | B12: 0 | D12: =IF(AND(p_aplicar_feriados=1,C12<>""),0,B12) -> 0 | E12: ESTIMADO
A13: 45669 | B13: 0 | D13: =IF(AND(p_aplicar_feriados=1,C13<>""),0,B13) -> 0 | E13: ESTIMADO
A14: 45670 | B14: 1 | D14: =IF(AND(p_aplicar_feriados=1,C14<>""),0,B14) -> 1 | E14: ESTIMADO
... A107: 45763 | B107: 1 | D107: =IF(AND(p_aplicar_feriados=1,C107<>""),0,B107) -> 1 | E107: ESTIMADO
A108: 45764 | B108: 1 | C108: Jueves Santo | D108: =IF(AND(p_aplicar_feriados=1,C108<>""),0,B108) -> 1 | E108: ESTIMADO
A109: 45765 | B109: 1 | C109: Viernes Santo | D109: =IF(AND(p_aplicar_feriados=1,C109<>""),0,B109) -> 1 | E109: ESTIMADO
A110: 45766 | B110: 0 | D110: =IF(AND(p_aplicar_feriados=1,C110<>""),0,B110) -> 0 | E110: ESTIMADO
A111: 45767 | B111: 0 | D111: =IF(AND(p_aplicar_feriados=1,C111<>""),0,B111) -> 0 | E111: ESTIMADO
A112: 45768 | B112: 1 | D112: =IF(AND(p_aplicar_feriados=1,C112<>""),0,B112) -> 1 | E112: ESTIMADO
A113: 45769 | B113: 1 | D113: =IF(AND(p_aplicar_feriados=1,C113<>""),0,B113) -> 1 | E113: ESTIMADO
A114: 45770 | B114: 1 | D114: =IF(AND(p_aplicar_feriados=1,C114<>""),0,B114) -> 1 | E114: ESTIMADO
A115: 45771 | B115: 1 | D115: =IF(AND(p_aplicar_feriados=1,C115<>""),0,B115) -> 1 | E115: ESTIMADO
A116: 45772 | B116: 1 | D116: =IF(AND(p_aplicar_feriados=1,C116<>""),0,B116) -> 1 | E116: ESTIMADO
A117: 45773 | B117: 0 | D117: =IF(AND(p_aplicar_feriados=1,C117<>""),0,B117) -> 0 | E117: ESTIMADO
A118: 45774 | B118: 0 | D118: =IF(AND(p_aplicar_feriados=1,C118<>""),0,B118) -> 0 | E118: ESTIMADO
A119: 45775 | B119: 1 | D119: =IF(AND(p_aplicar_feriados=1,C119<>""),0,B119) -> 1 | E119: ESTIMADO
A120: 45776 | B120: 1 | D120: =IF(AND(p_aplicar_feriados=1,C120<>""),0,B120) -> 1 | E120: ESTIMADO
A121: 45777 | B121: 1 | D121: =IF(AND(p_aplicar_feriados=1,C121<>""),0,B121) -> 1 | E121: ESTIMADO
A122: 45778 | B122: 1 | C122: Día del Trabajo | D122: =IF(AND(p_aplicar_feriados=1,C122<>""),0,B122) -> 1 | E122: ESTIMADO
A123: 45779 | B123: 1 | D123: =IF(AND(p_aplicar_feriados=1,C123<>""),0,B123) -> 1 | E123: ESTIMADO
A124: 45780 | B124: 0 | D124: =IF(AND(p_aplicar_feriados=1,C124<>""),0,B124) -> 0 | E124: ESTIMADO
A125: 45781 | B125: 0 | D125: =IF(AND(p_aplicar_feriados=1,C125<>""),0,B125) -> 0 | E125: ESTIMADO
A126: 45782 | B126: 1 | D126: =IF(AND(p_aplicar_feriados=1,C126<>""),0,B126) -> 1 | E126: ESTIMADO
A127: 45783 | B127: 1 | D127: =IF(AND(p_aplicar_feriados=1,C127<>""),0,B127) -> 1 | E127: ESTIMADO
A128: 45784 | B128: 1 | D128: =IF(AND(p_aplicar_feriados=1,C128<>""),0,B128) -> 1 | E128: ESTIMADO
A129: 45785 | B129: 1 | D129: =IF(AND(p_aplicar_feriados=1,C129<>""),0,B129) -> 1 | E129: ESTIMADO
A130: 45786 | B130: 1 | D130: =IF(AND(p_aplicar_feriados=1,C130<>""),0,B130) -> 1 | E130: ESTIMADO
A131: 45787 | B131: 0 | D131: =IF(AND(p_aplicar_feriados=1,C131<>""),0,B131) -> 0 | E131: ESTIMADO
A132: 45788 | B132: 0 | D132: =IF(AND(p_aplicar_feriados=1,C132<>""),0,B132) -> 0 | E132: ESTIMADO
...

Sheet 08_PEDIDOS
A1: Pedido | B1: Producto | C1: Familia | D1: Unidades | E1: Recepción 2025 | F1: Liberación 2025 | G1: Compromiso 2025 | H1: Lote | I1: Clasificación | J1: Precio familiar S/ | K1: Valor pedido S/ | L1: Penalidad fija S/ | M1: Plazo días | N1: Horas de proceso (ruta principal) | O1: Horas productivas disponibles r→d | P1: Ruta excede ventana (1/0) | Q1: Fecha en fin de semana (1/0) | R1: Producto válido (1/0) | S1: Naturaleza
A2: P001 | B2: Minirack metálico con bandejas | C2: Racks industriales | D2: 12 | E2: 45660 | F2: 45660 | G2: 45677 | H2: 10 | I2: SIMULADO | J2: =INDEX('12_PRECIOS'!$D$2:$D$5,MATCH(C2,'12_PRECIOS'!$A$2:$A$5,0)) -> 2650.49 | K2: =J2*D2 -> 31805.88 | L2: =K2*INDEX('12_PRECIOS'!$E$2:$E$5,MATCH(C2,'12_PRECIOS'!$A$2:$A$5,0)) -> 3180.588 | M2: =G2-E2 -> 17 | N2: =SUMIF('09_CARGA_ORDEN'!$A$2:$A$1153,A2,'09_CARGA_ORDEN'!$J$2:$J$1153) -> 90.66696 | O2: =SUMPRODUCT(('07_CALENDARIO'!$A$2:$A$397>=F2)*('07_CALENDARIO'!$A$2:$A$397<=G2)*'07_CALENDARIO'!$D$2:$D$397)*p_horas_productivas_dia -> 96 | P2: =IF(N2>O2+0.000001,1,0) -> 0 | Q2: =IF(OR(WEEKDAY(F2,2)>5,WEEKDAY(G2,2)>5),1,0) -> 0 | R2: =IF(COUNTIF('01_PRODUCTOS'!$B$2:$B$51,B2)>0,1,0) -> 1 | S2: SIMULADO
A3: P002 | B3: Estante reforzado modular | C3: Racks industriales | D3: 12 | E3: 45673 | F3: 45673 | G3: 45691 | H3: 10 | I3: SIMULADO | J3: =INDEX('12_PRECIOS'!$D$2:$D$5,MATCH(C3,'12_PRECIOS'!$A$2:$A$5,0)) -> 2650.49 | K3: =J3*D3 -> 31805.88 | L3: =K3*INDEX('12_PRECIOS'!$E$2:$E$5,MATCH(C3,'12_PRECIOS'!$A$2:$A$5,0)) -> 3180.588 | M3: =G3-E3 -> 18 | N3: =SUMIF('09_CARGA_ORDEN'!$A$2:$A$1153,A3,'09_CARGA_ORDEN'!$J$2:$J$1153) -> 100.7708 | O3: =SUMPRODUCT(('07_CALENDARIO'!$A$2:$A$397>=F3)*('07_CALENDARIO'!$A$2:$A$397<=G3)*'07_CALENDARIO'!$D$2:$D$397)*p_horas_productivas_dia -> 104 | P3: =IF(N3>O3+0.000001,1,0) -> 0 | Q3: =IF(OR(WEEKDAY(F3,2)>5,WEEKDAY(G3,2)>5),1,0) -> 0 | R3: =IF(COUNTIF('01_PRODUCTOS'!$B$2:$B$51,B3)>0,1,0) -> 1 | S3: SIMULADO
A4: P003 | B4: Góndola central comercial | C4: Góndolas comerciales | D4: 7 | E4: 45660 | F4: 45660 | G4: 45675 | H4: 10 | I4: SIMULADO | J4: =INDEX('12_PRECIOS'!$D$2:$D$5,MATCH(C4,'12_PRECIOS'!$A$2:$A$5,0)) -> 2150.57 | K4: =J4*D4 -> 15053.99 | L4: =K4*INDEX('12_PRECIOS'!$E$2:$E$5,MATCH(C4,'12_PRECIOS'!$A$2:$A$5,0)) -> 1505.399 | M4: =G4-E4 -> 15 | N4: =SUMIF('09_CARGA_ORDEN'!$A$2:$A$1153,A4,'09_CARGA_ORDEN'!$J$2:$J$1153) -> 68.444107 | O4: =SUMPRODUCT(('07_CALENDARIO'!$A$2:$A$397>=F4)*('07_CALENDARIO'!$A$2:$A$397<=G4)*'07_CALENDARIO'!$D$2:$D$397)*p_horas_productivas_dia -> 88 | P4: =IF(N4>O4+0.000001,1,0) -> 0 | Q4: =IF(OR(WEEKDAY(F4,2)>5,WEEKDAY(G4,2)>5),1,0) -> 1 | R4: =IF(COUNTIF('01_PRODUCTOS'!$B$2:$B$51,B4)>0,1,0) -> 1 | S4: SIMULADO
A5: P004 | B5: Góndola mural | C5: Góndolas comerciales | D5: 7 | E5: 45673 | F5: 45673 | G5: 45689 | H5: 10 | I5: SIMULADO | J5: =INDEX('12_PRECIOS'!$D$2:$D$5,MATCH(C5,'12_PRECIOS'!$A$2:$A$5,0)) -> 2150.57 | K5: =J5*D5 -> 15053.99 | L5: =K5*INDEX('12_PRECIOS'!$E$2:$E$5,MATCH(C5,'12_PRECIOS'!$A$2:$A$5,0)) -> 1505.399 | M5: =G5-E5 -> 16 | N5: =SUMIF('09_CARGA_ORDEN'!$A$2:$A$1153,A5,'09_CARGA_ORDEN'!$J$2:$J$1153) -> 47.37639 | O5: =SUMPRODUCT(('07_CALENDARIO'!$A$2:$A$397>=F5)*('07_CALENDARIO'!$A$2:$A$397<=G5)*'07_CALENDARIO'!$D$2:$D$397)*p_horas_productivas_dia -> 96 | P5: =IF(N5>O5+0.000001,1,0) -> 0 | Q5: =IF(OR(WEEKDAY(F5,2)>5,WEEKDAY(G5,2)>5),1,0) -> 1 | R5: =IF(COUNTIF('01_PRODUCTOS'!$B$2:$B$51,B5)>0,1,0) -> 1 | S5: SIMULADO
A6: P005 | B6: Locker de 4 puertas | C6: Lockers metálicos | D6: 6 | E6: 45660 | F6: 45660 | G6: 45674 | H6: 10 | I6: SIMULADO | J6: =INDEX('12_PRECIOS'!$D$2:$D$5,MATCH(C6,'12_PRECIOS'!$A$2:$A$5,0)) -> 1800.81 | K6: =J6*D6 -> 10804.86 | L6: =K6*INDEX('12_PRECIOS'!$E$2:$E$5,MATCH(C6,'12_PRECIOS'!$A$2:$A$5,0)) -> 1080.486 | M6: =G6-E6 -> 14 | N6: =SUMIF('09_CARGA_ORDEN'!$A$2:$A$1153,A6,'09_CARGA_ORDEN'!$J$2:$J$1153) -> 28.1919 | O6: =SUMPRODUCT(('07_CALENDARIO'!$A$2:$A$397>=F6)*('07_CALENDARIO'!$A$2:$A$397<=G6)*'07_CALENDARIO'!$D$2:$D$397)*p_horas_productivas_dia -> 88 | P6: =IF(N6>O6+0.000001,1,0) -> 0 | Q6: =IF(OR(WEEKDAY(F6,2)>5,WEEKDAY(G6,2)>5),1,0) -> 0 | R6: =IF(COUNTIF('01_PRODUCTOS'!$B$2:$B$51,B6)>0,1,0) -> 1 | S6: SIMULADO
A7: P006 | B7: Locker de 6 puertas | C7: Lockers metálicos | D7: 6 | E7: 45673 | F7: 45673 | G7: 45688 | H7: 10 | I7: SIMULADO | J7: =INDEX('12_PRECIOS'!$D$2:$D$5,MATCH(C7,'12_PRECIOS'!$A$2:$A$5,0)) -> 1800.81 | K7: =J7*D7 -> 10804.86 | L7: =K7*INDEX('12_PRECIOS'!$E$2:$E$5,MATCH(C7,'12_PRECIOS'!$A$2:$A$5,0)) -> 1080.486 | M7: =G7-E7 -> 15 | N7: =SUMIF('09_CARGA_ORDEN'!$A$2:$A$1153,A7,'09_CARGA_ORDEN'!$J$2:$J$1153) -> 38.8968 | O7: =SUMPRODUCT(('07_CALENDARIO'!$A$2:$A$397>=F7)*('07_CALENDARIO'!$A$2:$A$397<=G7)*'07_CALENDARIO'!$D$2:$D$397)*p_horas_productivas_dia -> 96 | P7: =IF(N7>O7+0.000001,1,0) -> 0 | Q7: =IF(OR(WEEKDAY(F7,2)>5,WEEKDAY(G7,2)>5),1,0) -> 0 | R7: =IF(COUNTIF('01_PRODUCTOS'!$B$2:$B$51,B7)>0,1,0) -> 1 | S7: SIMULADO
