Workbook

Sheet 00_DICCIONARIO
A1: hoja | B1: columna | C1: tipo | D1: unidad | E1: obligatorio_1_0 | F1: naturaleza | G1: descripcion | H1: usado_por_python
A2: 01_FAMILIAS | B2: familia_id | C2: texto | E2: 1 | F2: REAL | G2: Clave de familia.
A3: 01_FAMILIAS | B3: familia | C3: texto | E3: 1 | F3: REAL | G3: Familia productiva declarada por la empresa.
A4: 01_FAMILIAS | B4: unidades_vendidas_2025 | C4: entero | D4: und | E4: 1 | F4: REAL | G4: Unidades agregadas 2025 del archivo de la empresa. | H4: datos.leer → 12_PRECIOS (precio medio)
A5: 01_FAMILIAS | B5: ventas_2025_soles | C5: moneda S/ | D5: S/ | E5: 1 | F5: REAL | G5: Ventas agregadas 2025 del archivo de la empresa. | H5: datos.leer → 12_PRECIOS (precio medio)
A6: 01_FAMILIAS | B6: precio_promedio_soles | C6: moneda S/ | D6: S/ por und | E6: 1 | F6: CALCULADO | G6: Fórmula: ventas / unidades.
A7: 01_FAMILIAS | B7: penalidad_fija_frac | C7: fracción | D7: fracción | E7: 1 | F7: ESTIMADO | G7: Fracción del valor del pedido si se entrega tarde. | H7: Objetivo f1 (P_j)
A8: 01_FAMILIAS | B8: penalidad_diaria_frac | C8: fracción | D8: fracción/día | E8: 1 | F8: ESTIMADO | G8: Fracción diaria (0 = no se usa). | H8: datos.leer (no interviene en f1)
A9: 01_FAMILIAS | B9: naturaleza | C9: texto | E9: 1 | G9: Naturaleza principal de la fila.
A10: 02_PRODUCTOS | B10: producto_id | C10: texto | E10: 1 | G10: Clave de producto.
A11: 02_PRODUCTOS | B11: familia_id | C11: texto | E11: 1 | G11: Familia (01_FAMILIAS).
A12: 02_PRODUCTOS | B12: producto | C12: texto | E12: 1 | G12: Nombre del producto (clave que usa Python). | H12: datos.leer → 01_PRODUCTOS
A13: 02_PRODUCTOS | B13: tipo | C13: texto | E13: 1 | G13: Tipo comercial.
A14: 02_PRODUCTOS | B14: alto_cm | C14: decimal | D14: cm | E14: 1 | F14: ESTIMADO | G14: Alto exterior.
A15: 02_PRODUCTOS | B15: ancho_cm | C15: decimal | D15: cm | E15: 1 | F15: ESTIMADO | G15: Ancho exterior.
A16: 02_PRODUCTOS | B16: fondo_cm | C16: decimal | D16: cm | E16: 1 | F16: ESTIMADO | G16: Fondo exterior.
A17: 02_PRODUCTOS | B17: puertas | C17: entero | D17: und | E17: 0 | G17: Número de puertas (vacío = no aplica).
A18: 02_PRODUCTOS | B18: lote_guia_und | C18: entero | D18: und | E18: 1 | F18: ESTIMADO | G18: Tamaño de lote de fabricación. | H18: Lote por defecto del pedido; duración (ROUNDUP(q/lote)·setup)
A19: 02_PRODUCTOS | B19: n_componentes | C19: entero | E19: 1 | F19: CALCULADO | G19: Líneas de despiece (fórmula).
A20: 02_PRODUCTOS | B20: n_pasos_ruta | C20: entero | E20: 1 | F20: CALCULADO | G20: Pasos de ruta (fórmula).
A21: 02_PRODUCTOS | B21: dimensiones_genericas | C21: binario 0/1 | E21: 1 | F21: CALCULADO | G21: 1 si ≥5 productos comparten exactamente las mismas dimensiones (indicio de plantilla, no de medición).
A22: 02_PRODUCTOS | B22: naturaleza | C22: texto | E22: 1 | G22: Naturaleza principal de la fila.
A23: 03_MATERIALES | B23: material_id | C23: texto | E23: 1 | G23: Clave técnica del material.
A24: 03_MATERIALES | B24: material | C24: texto | E24: 1 | G24: Descripción.
A25: 03_MATERIALES | B25: grupo | C25: texto | E25: 1 | G25: Grupo normalizado.
A26: 03_MATERIALES | B26: unidad_costo | C26: texto | E26: 1 | G26: Unidad del costo unitario.
A27: 03_MATERIALES | B27: espesor_mm | C27: decimal | D27: mm | E27: 0 | G27: Espesor nominal (vacío = no especificado).
A28: 03_MATERIALES | B28: ancho_m | C28: decimal | D28: m | E28: 0 | G28: Ancho del formato de compra.
A29: 03_MATERIALES | B29: largo_m | C29: decimal | D29: m | E29: 0 | G29: Largo del formato de compra.
A30: 03_MATERIALES | B30: costo_unitario_soles | C30: moneda S/ | D30: S/ | E30: 0 | F30: ESTIMADO | G30: Costo por unidad de costo (vacío = sin cotización).
A31: 03_MATERIALES | B31: material_generico | C31: binario 0/1 | E31: 1 | G31: 1 = material genérico (sección o tipo por definir).
A32: 03_MATERIALES | B32: naturaleza | C32: texto | E32: 1 | G32: ESTIMADO si tiene costo; PENDIENTE si falta el costo.
A33: 04_DESPIECE | B33: bom_id | C33: texto | E33: 1 | G33: Clave de línea de despiece.
A34: 04_DESPIECE | B34: producto_id | C34: texto | E34: 1 | G34: Producto.
A35: 04_DESPIECE | B35: componente | C35: texto | E35: 1 | G35: Componente.
A36: 04_DESPIECE | B36: material_id | C36: texto | E36: 1 | G36: Material (03_MATERIALES).
A37: 04_DESPIECE | B37: tipo_calculo | C37: texto | E37: 1 | G37: CHAPA_AREA | PERFIL_LONGITUD | UNIDAD | SIN_PRECIO.
A38: 04_DESPIECE | B38: piezas_por_unidad | C38: entero | D38: pzas | E38: 1 | F38: ESTIMADO | G38: Piezas por unidad de producto.
A39: 04_DESPIECE | B39: ancho_pieza_mm | C39: decimal | D39: mm | E39: 0 | G39: Desarrollo de la pieza de chapa.
A40: 04_DESPIECE | B40: alto_pieza_mm | C40: decimal | D40: mm | E40: 0 | G40: Desarrollo de la pieza de chapa.
...

Sheet 00_CODIGOS
A1: codigo_naturaleza | B1: definicion
A2: REAL | B2: Dato declarado o respaldado por la empresa (p. ej. 25 trabajadores, 1 turno, ventas agregadas).
A3: REFERENCIA | B3: Dato público verificable ajeno a la empresa (ley, constante física, UIT, feriados oficiales).
A4: CALCULADO | B4: Resultado de una operación reproducible a partir de otros datos de la base.
A5: ESTIMADO | B5: Aproximación justificada (heredada, de catálogo o de ingeniería) que requiere validación en planta.
A6: SIMULADO | B6: Dato artificial creado para probar el modelo. No es historial ni registro de SAGAPI.
A7: CONFIGURACION | B7: Parámetro de ejecución del modelo o del experimento; no describe la planta.
A8: PENDIENTE | B8: Dato necesario que no existe en la base; se deja vacío a propósito (ver pendientes).
A10: LIBRO | B10: SAGAPI — Base de datos OPERATIVA v2.0 (datos reales, de referencia, calculados y estimados; sin datos simulados).
A11: VERSION_BD | B11: 2.0.0
A12: COLORES | B12: Texto azul = dato introducido; texto negro = fórmula; encabezado azul oscuro.
A13: FECHAS | B13: AAAA-MM-DD (fecha) y AAAA-MM-DD hh:mm:ss (fecha-hora).

Sheet 01_FAMILIAS
A1: familia_id | B1: familia | C1: unidades_vendidas_2025 | D1: ventas_2025_soles | E1: precio_promedio_soles | F1: penalidad_fija_frac | G1: penalidad_diaria_frac | H1: naturaleza
A2: FAM-RAC | B2: Racks industriales | C2: 295 | D2: 781894.55 | E2: =D2/C2 -> 2650.49 | F2: 0.1 | G2: 0 | H2: REAL
A3: FAM-GON | B3: Góndolas comerciales | C3: 167 | D3: 359145.19 | E3: =D3/C3 -> 2150.57 | F3: 0.1 | G3: 0 | H3: REAL
A4: FAM-LOC | B4: Lockers metálicos | C4: 139 | D4: 250312.59 | E4: =D4/C4 -> 1800.81 | F4: 0.1 | G4: 0 | H4: REAL
A5: FAM-OTR | B5: Otros productos metalmecánicos | C5: 250 | D5: 580617.45 | E5: =D5/C5 -> 2322.4698 | F5: 0.1 | G5: 0 | H5: REAL

Sheet 02_PRODUCTOS
A1: producto_id | B1: familia_id | C1: producto | D1: tipo | E1: alto_cm | F1: ancho_cm | G1: fondo_cm | H1: puertas | I1: lote_guia_und | J1: n_componentes | K1: n_pasos_ruta | L1: dimensiones_genericas | M1: naturaleza
A2: PRD-001 | B2: FAM-RAC | C2: Minirack metálico con bandejas | D2: Estantería liviana | E2: 200 | F2: 120 | G2: 60 | I2: 10 | J2: =COUNTIF('04_DESPIECE'!$B$2:$B$225,A2) -> 7 | K2: =COUNTIF('06_RUTAS'!$A$2:$A$407,A2) -> 13 | L2: =IF(COUNTIFS($E$2:$E$51,E2,$F$2:$F$51,F2,$G$2:$G$51,G2)>=5,1,0) -> 0 | M2: ESTIMADO
A3: PRD-002 | B3: FAM-RAC | C3: Estante reforzado modular | D3: Estantería reforzada | E3: 200 | F3: 120 | G3: 60 | I3: 10 | J3: =COUNTIF('04_DESPIECE'!$B$2:$B$225,A3) -> 6 | K3: =COUNTIF('06_RUTAS'!$A$2:$A$407,A3) -> 13 | L3: =IF(COUNTIFS($E$2:$E$51,E3,$F$2:$F$51,F3,$G$2:$G$51,G3)>=5,1,0) -> 0 | M3: ESTIMADO
A4: PRD-003 | B4: FAM-RAC | C4: Rack selectivo para pallets | D4: Selectivo | E4: 400 | F4: 270 | G4: 110 | I4: 10 | J4: =COUNTIF('04_DESPIECE'!$B$2:$B$225,A4) -> 4 | K4: =COUNTIF('06_RUTAS'!$A$2:$A$407,A4) -> 8 | L4: =IF(COUNTIFS($E$2:$E$51,E4,$F$2:$F$51,F4,$G$2:$G$51,G4)>=5,1,0) -> 0 | M4: ESTIMADO
A5: PRD-004 | B5: FAM-RAC | C5: Rack cantilever 3 niveles | D5: Cantilever | E5: 300 | F5: 150 | G5: 100 | I5: 10 | J5: =COUNTIF('04_DESPIECE'!$B$2:$B$225,A5) -> 4 | K5: =COUNTIF('06_RUTAS'!$A$2:$A$407,A5) -> 8 | L5: =IF(COUNTIFS($E$2:$E$51,E5,$F$2:$F$51,F5,$G$2:$G$51,G5)>=5,1,0) -> 0 | M5: ESTIMADO
A6: PRD-005 | B6: FAM-RAC | C6: Estantería metálica K45 5 niveles | D6: Picking | E6: 200 | F6: 120 | G6: 60 | I6: 10 | J6: =COUNTIF('04_DESPIECE'!$B$2:$B$225,A6) -> 4 | K6: =COUNTIF('06_RUTAS'!$A$2:$A$407,A6) -> 10 | L6: =IF(COUNTIFS($E$2:$E$51,E6,$F$2:$F$51,F6,$G$2:$G$51,G6)>=5,1,0) -> 0 | M6: ESTIMADO
A7: PRD-006 | B7: FAM-RAC | C7: Rack Mecano Strong MY-075-1 | D7: Semindustrial | E7: 200 | F7: 120 | G7: 60 | I7: 10 | J7: =COUNTIF('04_DESPIECE'!$B$2:$B$225,A7) -> 4 | K7: =COUNTIF('06_RUTAS'!$A$2:$A$407,A7) -> 8 | L7: =IF(COUNTIFS($E$2:$E$51,E7,$F$2:$F$51,F7,$G$2:$G$51,G7)>=5,1,0) -> 0 | M7: ESTIMADO
A8: PRD-007 | B8: FAM-GON | C8: Góndola central comercial | D8: Góndola central | E8: 160 | F8: 100 | G8: 90 | I8: 10 | J8: =COUNTIF('04_DESPIECE'!$B$2:$B$225,A8) -> 7 | K8: =COUNTIF('06_RUTAS'!$A$2:$A$407,A8) -> 12 | L8: =IF(COUNTIFS($E$2:$E$51,E8,$F$2:$F$51,F8,$G$2:$G$51,G8)>=5,1,0) -> 0 | M8: ESTIMADO
A9: PRD-008 | B9: FAM-GON | C9: Góndola mural | D9: Góndola mural | E9: 200 | F9: 100 | G9: 45 | I9: 10 | J9: =COUNTIF('04_DESPIECE'!$B$2:$B$225,A9) -> 6 | K9: =COUNTIF('06_RUTAS'!$A$2:$A$407,A9) -> 13 | L9: =IF(COUNTIFS($E$2:$E$51,E9,$F$2:$F$51,F9,$G$2:$G$51,G9)>=5,1,0) -> 0 | M9: ESTIMADO
A10: PRD-009 | B10: FAM-GON | C10: Góndola central doble forro liso | D10: Central | E10: 160 | F10: 100 | G10: 90 | I10: 10 | J10: =COUNTIF('04_DESPIECE'!$B$2:$B$225,A10) -> 5 | K10: =COUNTIF('06_RUTAS'!$A$2:$A$407,A10) -> 10 | L10: =IF(COUNTIFS($E$2:$E$51,E10,$F$2:$F$51,F10,$G$2:$G$51,G10)>=5,1,0) -> 0 | M10: ESTIMADO
A11: PRD-010 | B11: FAM-GON | C11: Góndola mural de forro liso | D11: Pared | E11: 200 | F11: 100 | G11: 45 | I11: 10 | J11: =COUNTIF('04_DESPIECE'!$B$2:$B$225,A11) -> 5 | K11: =COUNTIF('06_RUTAS'!$A$2:$A$407,A11) -> 10 | L11: =IF(COUNTIFS($E$2:$E$51,E11,$F$2:$F$51,F11,$G$2:$G$51,G11)>=5,1,0) -> 0 | M11: ESTIMADO
A12: PRD-011 | B12: FAM-GON | C12: Góndola de cabecera liso | D12: Cabecera | E12: 150 | F12: 90 | G12: 45 | I12: 10 | J12: =COUNTIF('04_DESPIECE'!$B$2:$B$225,A12) -> 5 | K12: =COUNTIF('06_RUTAS'!$A$2:$A$407,A12) -> 10 | L12: =IF(COUNTIFS($E$2:$E$51,E12,$F$2:$F$51,F12,$G$2:$G$51,G12)>=5,1,0) -> 0 | M12: ESTIMADO
A13: PRD-012 | B13: FAM-GON | C13: Góndola isla modular | D13: Isla | E13: 160 | F13: 100 | G13: 90 | I13: 10 | J13: =COUNTIF('04_DESPIECE'!$B$2:$B$225,A13) -> 5 | K13: =COUNTIF('06_RUTAS'!$A$2:$A$407,A13) -> 10 | L13: =IF(COUNTIFS($E$2:$E$51,E13,$F$2:$F$51,F13,$G$2:$G$51,G13)>=5,1,0) -> 0 | M13: ESTIMADO
A14: PRD-013 | B14: FAM-LOC | C14: Locker de 4 puertas | D14: Locker de 4 compartimentos | E14: 180 | F14: 80 | G14: 45 | H14: 4 | I14: 10 | J14: =COUNTIF('04_DESPIECE'!$B$2:$B$225,A14) -> 7 | K14: =COUNTIF('06_RUTAS'!$A$2:$A$407,A14) -> 11 | L14: =IF(COUNTIFS($E$2:$E$51,E14,$F$2:$F$51,F14,$G$2:$G$51,G14)>=5,1,0) -> 0 | M14: ESTIMADO
A15: PRD-014 | B15: FAM-LOC | C15: Locker de 6 puertas | D15: Locker de 6 compartimentos | E15: 180 | F15: 80 | G15: 45 | H15: 6 | I15: 10 | J15: =COUNTIF('04_DESPIECE'!$B$2:$B$225,A15) -> 8 | K15: =COUNTIF('06_RUTAS'!$A$2:$A$407,A15) -> 11 | L15: =IF(COUNTIFS($E$2:$E$51,E15,$F$2:$F$51,F15,$G$2:$G$51,G15)>=5,1,0) -> 0 | M15: ESTIMADO
A16: PRD-015 | B16: FAM-LOC | C16: Locker metálico simple MK1-01 | D16: 1 puertas | E16: 180 | F16: 40 | G16: 45 | H16: 1 | I16: 10 | J16: =COUNTIF('04_DESPIECE'!$B$2:$B$225,A16) -> 5 | K16: =COUNTIF('06_RUTAS'!$A$2:$A$407,A16) -> 8 | L16: =IF(COUNTIFS($E$2:$E$51,E16,$F$2:$F$51,F16,$G$2:$G$51,G16)>=5,1,0) -> 0 | M16: ESTIMADO
A17: PRD-016 | B17: FAM-LOC | C17: Locker metálico simple MK2-01 | D17: 2 puertas | E17: 180 | F17: 40 | G17: 45 | H17: 2 | I17: 10 | J17: =COUNTIF('04_DESPIECE'!$B$2:$B$225,A17) -> 5 | K17: =COUNTIF('06_RUTAS'!$A$2:$A$407,A17) -> 8 | L17: =IF(COUNTIFS($E$2:$E$51,E17,$F$2:$F$51,F17,$G$2:$G$51,G17)>=5,1,0) -> 0 | M17: ESTIMADO
A18: PRD-017 | B18: FAM-LOC | C18: Locker metálico simple MK3-01 | D18: 3 puertas | E18: 180 | F18: 40 | G18: 45 | H18: 3 | I18: 10 | J18: =COUNTIF('04_DESPIECE'!$B$2:$B$225,A18) -> 5 | K18: =COUNTIF('06_RUTAS'!$A$2:$A$407,A18) -> 8 | L18: =IF(COUNTIFS($E$2:$E$51,E18,$F$2:$F$51,F18,$G$2:$G$51,G18)>=5,1,0) -> 0 | M18: ESTIMADO
A19: PRD-018 | B19: FAM-LOC | C19: Locker metálico simple MK4-01 | D19: 4 puertas | E19: 180 | F19: 40 | G19: 45 | H19: 4 | I19: 10 | J19: =COUNTIF('04_DESPIECE'!$B$2:$B$225,A19) -> 5 | K19: =COUNTIF('06_RUTAS'!$A$2:$A$407,A19) -> 8 | L19: =IF(COUNTIFS($E$2:$E$51,E19,$F$2:$F$51,F19,$G$2:$G$51,G19)>=5,1,0) -> 0 | M19: ESTIMADO
A20: PRD-019 | B20: FAM-OTR | C20: Armario metálico | D20: Gabinete metálico | E20: 85 | F20: 120 | G20: 60 | I20: 10 | J20: =COUNTIF('04_DESPIECE'!$B$2:$B$225,A20) -> 7 | K20: =COUNTIF('06_RUTAS'!$A$2:$A$407,A20) -> 11 | L20: =IF(COUNTIFS($E$2:$E$51,E20,$F$2:$F$51,F20,$G$2:$G$51,G20)>=5,1,0) -> 1 | M20: ESTIMADO
A21: PRD-020 | B21: FAM-OTR | C21: Estantería liviana metálica | D21: Estantería liviana | E21: 85 | F21: 120 | G21: 60 | I21: 10 | J21: =COUNTIF('04_DESPIECE'!$B$2:$B$225,A21) -> 5 | K21: =COUNTIF('06_RUTAS'!$A$2:$A$407,A21) -> 12 | L21: =IF(COUNTIFS($E$2:$E$51,E21,$F$2:$F$51,F21,$G$2:$G$51,G21)>=5,1,0) -> 1 | M21: ESTIMADO
A22: PRD-021 | B22: FAM-OTR | C22: Silla fija PC0173 | D22: Silla | E22: 85 | F22: 45 | G22: 50 | I22: 10 | J22: =COUNTIF('04_DESPIECE'!$B$2:$B$225,A22) -> 3 | K22: =COUNTIF('06_RUTAS'!$A$2:$A$407,A22) -> 8 | L22: =IF(COUNTIFS($E$2:$E$51,E22,$F$2:$F$51,F22,$G$2:$G$51,G22)>=5,1,0) -> 1 | M22: ESTIMADO
A23: PRD-022 | B23: FAM-OTR | C23: Silla capacitación 105 | D23: Silla | E23: 85 | F23: 45 | G23: 50 | I23: 10 | J23: =COUNTIF('04_DESPIECE'!$B$2:$B$225,A23) -> 3 | K23: =COUNTIF('06_RUTAS'!$A$2:$A$407,A23) -> 2 | L23: =IF(COUNTIFS($E$2:$E$51,E23,$F$2:$F$51,F23,$G$2:$G$51,G23)>=5,1,0) -> 1 | M23: ESTIMADO
A24: PRD-023 | B24: FAM-OTR | C24: Cajonera metálica P1019 | D24: Archivador | E24: 85 | F24: 120 | G24: 60 | I24: 10 | J24: =COUNTIF('04_DESPIECE'!$B$2:$B$225,A24) -> 4 | K24: =COUNTIF('06_RUTAS'!$A$2:$A$407,A24) -> 8 | L24: =IF(COUNTIFS($E$2:$E$51,E24,$F$2:$F$51,F24,$G$2:$G$51,G24)>=5,1,0) -> 1 | M24: ESTIMADO
A25: PRD-024 | B25: FAM-OTR | C25: Archivador metálico 3 cajones | D25: Archivador | E25: 85 | F25: 120 | G25: 60 | I25: 10 | J25: =COUNTIF('04_DESPIECE'!$B$2:$B$225,A25) -> 4 | K25: =COUNTIF('06_RUTAS'!$A$2:$A$407,A25) -> 8 | L25: =IF(COUNTIFS($E$2:$E$51,E25,$F$2:$F$51,F25,$G$2:$G$51,G25)>=5,1,0) -> 1 | M25: ESTIMADO
A26: PRD-025 | B26: FAM-OTR | C26: Archivador metálico 4 cajones | D26: Archivador | E26: 85 | F26: 120 | G26: 60 | I26: 10 | J26: =COUNTIF('04_DESPIECE'!$B$2:$B$225,A26) -> 4 | K26: =COUNTIF('06_RUTAS'!$A$2:$A$407,A26) -> 8 | L26: =IF(COUNTIFS($E$2:$E$51,E26,$F$2:$F$51,F26,$G$2:$G$51,G26)>=5,1,0) -> 1 | M26: ESTIMADO
A27: PRD-026 | B27: FAM-OTR | C27: Armario metálico KD-034 | D27: Gabinete | E27: 85 | F27: 120 | G27: 60 | I27: 10 | J27: =COUNTIF('04_DESPIECE'!$B$2:$B$225,A27) -> 4 | K27: =COUNTIF('06_RUTAS'!$A$2:$A$407,A27) -> 8 | L27: =IF(COUNTIFS($E$2:$E$51,E27,$F$2:$F$51,F27,$G$2:$G$51,G27)>=5,1,0) -> 1 | M27: ESTIMADO
A28: PRD-027 | B28: FAM-OTR | C28: Banqueta con patas metálicas | D28: Banco | E28: 85 | F28: 120 | G28: 60 | I28: 10 | J28: =COUNTIF('04_DESPIECE'!$B$2:$B$225,A28) -> 4 | K28: =COUNTIF('06_RUTAS'!$A$2:$A$407,A28) -> 8 | L28: =IF(COUNTIFS($E$2:$E$51,E28,$F$2:$F$51,F28,$G$2:$G$51,G28)>=5,1,0) -> 1 | M28: ESTIMADO
A29: PRD-028 | B29: FAM-OTR | C29: Armario herramientas MY-TC-03 | D29: Gabinete | E29: 85 | F29: 120 | G29: 60 | I29: 10 | J29: =COUNTIF('04_DESPIECE'!$B$2:$B$225,A29) -> 4 | K29: =COUNTIF('06_RUTAS'!$A$2:$A$407,A29) -> 8 | L29: =IF(COUNTIFS($E$2:$E$51,E29,$F$2:$F$51,F29,$G$2:$G$51,G29)>=5,1,0) -> 1 | M29: ESTIMADO
A30: PRD-029 | B30: FAM-OTR | C30: Armario herramientas MY-TC-04 | D30: Gabinete | E30: 85 | F30: 120 | G30: 60 | I30: 10 | J30: =COUNTIF('04_DESPIECE'!$B$2:$B$225,A30) -> 4 | K30: =COUNTIF('06_RUTAS'!$A$2:$A$407,A30) -> 8 | L30: =IF(COUNTIFS($E$2:$E$51,E30,$F$2:$F$51,F30,$G$2:$G$51,G30)>=5,1,0) -> 1 | M30: ESTIMADO
A31: PRD-030 | B31: FAM-OTR | C31: Armario herramientas MY-TC-05 | D31: Gabinete | E31: 85 | F31: 120 | G31: 60 | I31: 10 | J31: =COUNTIF('04_DESPIECE'!$B$2:$B$225,A31) -> 4 | K31: =COUNTIF('06_RUTAS'!$A$2:$A$407,A31) -> 8 | L31: =IF(COUNTIFS($E$2:$E$51,E31,$F$2:$F$51,F31,$G$2:$G$51,G31)>=5,1,0) -> 1 | M31: ESTIMADO
... A51: PRD-050 | B51: FAM-OTR | C51: Silla terraza New Bistro | D51: Silla | E51: 85 | F51: 45 | G51: 50 | I51: 10 | J51: =COUNTIF('04_DESPIECE'!$B$2:$B$225,A51) -> 3 | K51: =COUNTIF('06_RUTAS'!$A$2:$A$407,A51) -> 8 | L51: =IF(COUNTIFS($E$2:$E$51,E51,$F$2:$F$51,F51,$G$2:$G$51,G51)>=5,1,0) -> 1 | M51: ESTIMADO

Sheet 03_MATERIALES
A1: material_id | B1: material | C1: grupo | D1: unidad_costo | E1: espesor_mm | F1: ancho_m | G1: largo_m | H1: costo_unitario_soles | I1: material_generico | J1: naturaleza
A2: MAT-LAC2 | B2: Plancha de acero laminado en caliente de 2 mm, 1.20 × 2.40 m | C2: CHAPA | D2: kg | E2: 2 | F2: 1.2 | G2: 2.4 | H2: 6.8 | I2: 0 | J2: ESTIMADO
A3: MAT-CH-1.0 | B3: Lámina LAF o acero 1.0 mm (alternativa V4) | C3: CHAPA | D3: kg | E3: 1 | H3: 6.8 | I3: 0 | J3: ESTIMADO
A4: MAT-CH-1.5 | B4: Lámina LAF o acero 1.5 mm (alternativa V4) | C4: CHAPA | D4: kg | E4: 1.5 | H4: 6.8 | I4: 0 | J4: ESTIMADO
A5: MAT-LAF06 | B5: Lámina LAF 0.6 mm (catálogo lockers) | C5: CHAPA | D5: kg | E5: 0.6 | H5: 6.8 | I5: 0 | J5: ESTIMADO
A6: MAT-LAF08 | B6: Lámina LAF 0.8 mm (catálogo góndolas) | C6: CHAPA | D6: kg | E6: 0.8 | H6: 6.8 | I6: 0 | J6: ESTIMADO
A7: MAT-LAF12 | B7: Lámina LAF 1.2 mm (taller) | C7: CHAPA | D7: kg | E7: 1.2 | H7: 6.8 | I7: 0 | J7: ESTIMADO
A8: MAT-PR-1 | B8: Tubo o perfil de acero (sección por definir) | C8: PERFIL | D8: m | H8: 6.1 | I8: 1 | J8: ESTIMADO
A9: MAT-FIJ | B9: Elementos de fijación metálica (tipo por desagregar) | C9: HERRAJE | D9: und | H9: 0.9 | I9: 1 | J9: ESTIMADO
A10: MAT-MEL18 | B10: Tablero melamina/MDP 18 mm comprado | C10: OTRO | D10: und | E10: 18 | I10: 0 | J10: PENDIENTE
A11: MAT-OTR | B11: Asiento, ruedas, vidrio, PVC o mecanismos comprados | C11: OTRO | D11: und | I11: 1 | J11: PENDIENTE
A12: COM-001 | B12: Pintura electrostática en polvo poliéster | C12: PINTURA | D12: kg | I12: 0 | J12: PENDIENTE
A13: COM-002 | B13: Pintura en polvo epoxi-poliéster | C13: PINTURA | D13: kg | I13: 0 | J13: PENDIENTE
A14: COM-003 | B14: Desengrasante industrial | C14: PREPARACION_SUPERFICIAL | D14: l | I14: 0 | J14: PENDIENTE
A15: COM-004 | B15: Disco abrasivo de corte | C15: CONSUMIBLE | D15: und | I15: 0 | J15: PENDIENTE
A16: COM-005 | B16: Disco abrasivo para desbarbado | C16: CONSUMIBLE | D16: und | I16: 0 | J16: PENDIENTE
A17: COM-006 | B17: Alambre para soldadura MIG/MAG | C17: SOLDADURA | D17: kg | I17: 0 | J17: PENDIENTE
A18: COM-007 | B18: Electrodo revestido para soldadura | C18: SOLDADURA | D18: kg | I18: 0 | J18: PENDIENTE
A19: COM-008 | B19: Gas protector para soldadura MIG/MAG | C19: SOLDADURA | D19: m3 | I19: 0 | J19: PENDIENTE
A20: COM-009 | B20: Tubo cuadrado de acero 30 × 30 mm | C20: PERFIL | D20: m | I20: 0 | J20: PENDIENTE
A21: COM-010 | B21: Tubo cuadrado de acero 40 × 40 mm | C21: PERFIL | D21: m | I21: 0 | J21: PENDIENTE
A22: COM-011 | B22: Ángulo de acero estructural | C22: PERFIL | D22: m | I22: 0 | J22: PENDIENTE
... A42: COM-031 | B42: Guante anticorte reutilizable | C42: SEGURIDAD | D42: par | I42: 0 | J42: PENDIENTE

Sheet 04_DESPIECE
A1: bom_id | B1: producto_id | C1: componente | D1: material_id | E1: tipo_calculo | F1: piezas_por_unidad | G1: ancho_pieza_mm | H1: alto_pieza_mm | I1: longitud_pieza_m | J1: area_chapa_m2_pieza | K1: masa_kg_producto | L1: costo_soles_producto | M1: planchas_equiv_producto | N1: naturaleza
A2: BOM-0001 | B2: PRD-001 | C2: Parante vertical | D2: MAT-PR-1 | E2: PERFIL_LONGITUD | F2: 4 | I2: 1.8 | K2: =IF(E2="CHAPA_AREA",F2*J2*INDEX('03_MATERIALES'!$E$2:$E$42,MATCH(D2,'03_MATERIALES'!$A$2:$A$42,0))/1000*p_densidad_acero,IF(E2="PERFIL_LONGITUD",F2*I2*p_kg_por_m_perfil,"")) -> 10.8 | L2: =IF(E2="CHAPA_AREA",K2*INDEX('03_MATERIALES'!$H$2:$H$42,MATCH(D2,'03_MATERIALES'!$A$2:$A$42,0))/p_aprovechamiento_chapa,IF(E2="PERFIL_LONGITUD",K2*INDEX('03_MATERIALES'!$H$2:$H$42,MATCH(D2,'03_MATERIALES'!$A$2:$A$42,0))/p_aprovechamiento_perfil,IF(E2="UNIDAD",F2*INDEX('03_MATERIALES'!$H$2:$H$42,MATCH(D2,'03_MATERIALES'!$A$2:$A$42,0)),""))) -> 68.625 | M2: =IF(N(J2)>0,F2*J2/p_area_plancha_m2,"") | N2: ESTIMADO
A3: BOM-0002 | B3: PRD-001 | C3: Larguero horizontal | D3: MAT-PR-1 | E3: PERFIL_LONGITUD | F3: 8 | I3: 1.2 | K3: =IF(E3="CHAPA_AREA",F3*J3*INDEX('03_MATERIALES'!$E$2:$E$42,MATCH(D3,'03_MATERIALES'!$A$2:$A$42,0))/1000*p_densidad_acero,IF(E3="PERFIL_LONGITUD",F3*I3*p_kg_por_m_perfil,"")) -> 14.4 | L3: =IF(E3="CHAPA_AREA",K3*INDEX('03_MATERIALES'!$H$2:$H$42,MATCH(D3,'03_MATERIALES'!$A$2:$A$42,0))/p_aprovechamiento_chapa,IF(E3="PERFIL_LONGITUD",K3*INDEX('03_MATERIALES'!$H$2:$H$42,MATCH(D3,'03_MATERIALES'!$A$2:$A$42,0))/p_aprovechamiento_perfil,IF(E3="UNIDAD",F3*INDEX('03_MATERIALES'!$H$2:$H$42,MATCH(D3,'03_MATERIALES'!$A$2:$A$42,0)),""))) -> 91.5 | M3: =IF(N(J3)>0,F3*J3/p_area_plancha_m2,"") | N3: ESTIMADO
A4: BOM-0003 | B4: PRD-001 | C4: Refuerzo transversal | D4: MAT-PR-1 | E4: PERFIL_LONGITUD | F4: 4 | I4: 0.6 | K4: =IF(E4="CHAPA_AREA",F4*J4*INDEX('03_MATERIALES'!$E$2:$E$42,MATCH(D4,'03_MATERIALES'!$A$2:$A$42,0))/1000*p_densidad_acero,IF(E4="PERFIL_LONGITUD",F4*I4*p_kg_por_m_perfil,"")) -> 3.6 | L4: =IF(E4="CHAPA_AREA",K4*INDEX('03_MATERIALES'!$H$2:$H$42,MATCH(D4,'03_MATERIALES'!$A$2:$A$42,0))/p_aprovechamiento_chapa,IF(E4="PERFIL_LONGITUD",K4*INDEX('03_MATERIALES'!$H$2:$H$42,MATCH(D4,'03_MATERIALES'!$A$2:$A$42,0))/p_aprovechamiento_perfil,IF(E4="UNIDAD",F4*INDEX('03_MATERIALES'!$H$2:$H$42,MATCH(D4,'03_MATERIALES'!$A$2:$A$42,0)),""))) -> 22.875 | M4: =IF(N(J4)>0,F4*J4/p_area_plancha_m2,"") | N4: ESTIMADO
A5: BOM-0004 | B5: PRD-001 | C5: Bandeja acero | D5: MAT-LAC2 | E5: CHAPA_AREA | F5: 4 | J5: 0.72 | K5: =IF(E5="CHAPA_AREA",F5*J5*INDEX('03_MATERIALES'!$E$2:$E$42,MATCH(D5,'03_MATERIALES'!$A$2:$A$42,0))/1000*p_densidad_acero,IF(E5="PERFIL_LONGITUD",F5*I5*p_kg_por_m_perfil,"")) -> 45.216 | L5: =IF(E5="CHAPA_AREA",K5*INDEX('03_MATERIALES'!$H$2:$H$42,MATCH(D5,'03_MATERIALES'!$A$2:$A$42,0))/p_aprovechamiento_chapa,IF(E5="PERFIL_LONGITUD",K5*INDEX('03_MATERIALES'!$H$2:$H$42,MATCH(D5,'03_MATERIALES'!$A$2:$A$42,0))/p_aprovechamiento_perfil,IF(E5="UNIDAD",F5*INDEX('03_MATERIALES'!$H$2:$H$42,MATCH(D5,'03_MATERIALES'!$A$2:$A$42,0)),""))) -> 334.20522 | M5: =IF(N(J5)>0,F5*J5/p_area_plancha_m2,"") -> 1 | N5: ESTIMADO
A6: BOM-0005 | B6: PRD-001 | C6: Cartela unión | D6: MAT-LAC2 | E6: CHAPA_AREA | F6: 8 | J6: 0.025 | K6: =IF(E6="CHAPA_AREA",F6*J6*INDEX('03_MATERIALES'!$E$2:$E$42,MATCH(D6,'03_MATERIALES'!$A$2:$A$42,0))/1000*p_densidad_acero,IF(E6="PERFIL_LONGITUD",F6*I6*p_kg_por_m_perfil,"")) -> 3.14 | L6: =IF(E6="CHAPA_AREA",K6*INDEX('03_MATERIALES'!$H$2:$H$42,MATCH(D6,'03_MATERIALES'!$A$2:$A$42,0))/p_aprovechamiento_chapa,IF(E6="PERFIL_LONGITUD",K6*INDEX('03_MATERIALES'!$H$2:$H$42,MATCH(D6,'03_MATERIALES'!$A$2:$A$42,0))/p_aprovechamiento_perfil,IF(E6="UNIDAD",F6*INDEX('03_MATERIALES'!$H$2:$H$42,MATCH(D6,'03_MATERIALES'!$A$2:$A$42,0)),""))) -> 23.208696 | M6: =IF(N(J6)>0,F6*J6/p_area_plancha_m2,"") -> 0.069444444 | N6: ESTIMADO
A7: BOM-0006 | B7: PRD-001 | C7: Tornillería sujeción | D7: MAT-FIJ | E7: UNIDAD | F7: 24 | K7: =IF(E7="CHAPA_AREA",F7*J7*INDEX('03_MATERIALES'!$E$2:$E$42,MATCH(D7,'03_MATERIALES'!$A$2:$A$42,0))/1000*p_densidad_acero,IF(E7="PERFIL_LONGITUD",F7*I7*p_kg_por_m_perfil,"")) | L7: =IF(E7="CHAPA_AREA",K7*INDEX('03_MATERIALES'!$H$2:$H$42,MATCH(D7,'03_MATERIALES'!$A$2:$A$42,0))/p_aprovechamiento_chapa,IF(E7="PERFIL_LONGITUD",K7*INDEX('03_MATERIALES'!$H$2:$H$42,MATCH(D7,'03_MATERIALES'!$A$2:$A$42,0))/p_aprovechamiento_perfil,IF(E7="UNIDAD",F7*INDEX('03_MATERIALES'!$H$2:$H$42,MATCH(D7,'03_MATERIALES'!$A$2:$A$42,0)),""))) -> 21.6 | M7: =IF(N(J7)>0,F7*J7/p_area_plancha_m2,"") | N7: ESTIMADO
A8: BOM-0007 | B8: PRD-001 | C8: Tapa protectora | D8: MAT-FIJ | E8: UNIDAD | F8: 4 | K8: =IF(E8="CHAPA_AREA",F8*J8*INDEX('03_MATERIALES'!$E$2:$E$42,MATCH(D8,'03_MATERIALES'!$A$2:$A$42,0))/1000*p_densidad_acero,IF(E8="PERFIL_LONGITUD",F8*I8*p_kg_por_m_perfil,"")) | L8: =IF(E8="CHAPA_AREA",K8*INDEX('03_MATERIALES'!$H$2:$H$42,MATCH(D8,'03_MATERIALES'!$A$2:$A$42,0))/p_aprovechamiento_chapa,IF(E8="PERFIL_LONGITUD",K8*INDEX('03_MATERIALES'!$H$2:$H$42,MATCH(D8,'03_MATERIALES'!$A$2:$A$42,0))/p_aprovechamiento_perfil,IF(E8="UNIDAD",F8*INDEX('03_MATERIALES'!$H$2:$H$42,MATCH(D8,'03_MATERIALES'!$A$2:$A$42,0)),""))) -> 3.6 | M8: =IF(N(J8)>0,F8*J8/p_area_plancha_m2,"") | N8: ESTIMADO
A9: BOM-0008 | B9: PRD-002 | C9: Parante perfil | D9: MAT-PR-1 | E9: PERFIL_LONGITUD | F9: 4 | I9: 2 | K9: =IF(E9="CHAPA_AREA",F9*J9*INDEX('03_MATERIALES'!$E$2:$E$42,MATCH(D9,'03_MATERIALES'!$A$2:$A$42,0))/1000*p_densidad_acero,IF(E9="PERFIL_LONGITUD",F9*I9*p_kg_por_m_perfil,"")) -> 12 | L9: =IF(E9="CHAPA_AREA",K9*INDEX('03_MATERIALES'!$H$2:$H$42,MATCH(D9,'03_MATERIALES'!$A$2:$A$42,0))/p_aprovechamiento_chapa,IF(E9="PERFIL_LONGITUD",K9*INDEX('03_MATERIALES'!$H$2:$H$42,MATCH(D9,'03_MATERIALES'!$A$2:$A$42,0))/p_aprovechamiento_perfil,IF(E9="UNIDAD",F9*INDEX('03_MATERIALES'!$H$2:$H$42,MATCH(D9,'03_MATERIALES'!$A$2:$A$42,0)),""))) -> 76.25 | M9: =IF(N(J9)>0,F9*J9/p_area_plancha_m2,"") | N9: ESTIMADO
A10: BOM-0009 | B10: PRD-002 | C10: Travesaño frontal | D10: MAT-PR-1 | E10: PERFIL_LONGITUD | F10: 8 | I10: 1 | K10: =IF(E10="CHAPA_AREA",F10*J10*INDEX('03_MATERIALES'!$E$2:$E$42,MATCH(D10,'03_MATERIALES'!$A$2:$A$42,0))/1000*p_densidad_acero,IF(E10="PERFIL_LONGITUD",F10*I10*p_kg_por_m_perfil,"")) -> 12 | L10: =IF(E10="CHAPA_AREA",K10*INDEX('03_MATERIALES'!$H$2:$H$42,MATCH(D10,'03_MATERIALES'!$A$2:$A$42,0))/p_aprovechamiento_chapa,IF(E10="PERFIL_LONGITUD",K10*INDEX('03_MATERIALES'!$H$2:$H$42,MATCH(D10,'03_MATERIALES'!$A$2:$A$42,0))/p_aprovechamiento_perfil,IF(E10="UNIDAD",F10*INDEX('03_MATERIALES'!$H$2:$H$42,MATCH(D10,'03_MATERIALES'!$A$2:$A$42,0)),""))) -> 76.25 | M10: =IF(N(J10)>0,F10*J10/p_area_plancha_m2,"") | N10: ESTIMADO
A11: BOM-0010 | B11: PRD-002 | C11: Travesaño lateral | D11: MAT-PR-1 | E11: PERFIL_LONGITUD | F11: 8 | I11: 0.5 | K11: =IF(E11="CHAPA_AREA",F11*J11*INDEX('03_MATERIALES'!$E$2:$E$42,MATCH(D11,'03_MATERIALES'!$A$2:$A$42,0))/1000*p_densidad_acero,IF(E11="PERFIL_LONGITUD",F11*I11*p_kg_por_m_perfil,"")) -> 6 | L11: =IF(E11="CHAPA_AREA",K11*INDEX('03_MATERIALES'!$H$2:$H$42,MATCH(D11,'03_MATERIALES'!$A$2:$A$42,0))/p_aprovechamiento_chapa,IF(E11="PERFIL_LONGITUD",K11*INDEX('03_MATERIALES'!$H$2:$H$42,MATCH(D11,'03_MATERIALES'!$A$2:$A$42,0))/p_aprovechamiento_perfil,IF(E11="UNIDAD",F11*INDEX('03_MATERIALES'!$H$2:$H$42,MATCH(D11,'03_MATERIALES'!$A$2:$A$42,0)),""))) -> 38.125 | M11: =IF(N(J11)>0,F11*J11/p_area_plancha_m2,"") | N11: ESTIMADO
A12: BOM-0011 | B12: PRD-002 | C12: Bandeja reforzada | D12: MAT-LAC2 | E12: CHAPA_AREA | F12: 5 | J12: 0.5 | K12: =IF(E12="CHAPA_AREA",F12*J12*INDEX('03_MATERIALES'!$E$2:$E$42,MATCH(D12,'03_MATERIALES'!$A$2:$A$42,0))/1000*p_densidad_acero,IF(E12="PERFIL_LONGITUD",F12*I12*p_kg_por_m_perfil,"")) -> 39.25 | L12: =IF(E12="CHAPA_AREA",K12*INDEX('03_MATERIALES'!$H$2:$H$42,MATCH(D12,'03_MATERIALES'!$A$2:$A$42,0))/p_aprovechamiento_chapa,IF(E12="PERFIL_LONGITUD",K12*INDEX('03_MATERIALES'!$H$2:$H$42,MATCH(D12,'03_MATERIALES'!$A$2:$A$42,0))/p_aprovechamiento_perfil,IF(E12="UNIDAD",F12*INDEX('03_MATERIALES'!$H$2:$H$42,MATCH(D12,'03_MATERIALES'!$A$2:$A$42,0)),""))) -> 290.1087 | M12: =IF(N(J12)>0,F12*J12/p_area_plancha_m2,"") -> 0.86805556 | N12: ESTIMADO
A13: BOM-0012 | B13: PRD-002 | C13: Cartela | D13: MAT-LAC2 | E13: CHAPA_AREA | F13: 8 | J13: 0.035 | K13: =IF(E13="CHAPA_AREA",F13*J13*INDEX('03_MATERIALES'!$E$2:$E$42,MATCH(D13,'03_MATERIALES'!$A$2:$A$42,0))/1000*p_densidad_acero,IF(E13="PERFIL_LONGITUD",F13*I13*p_kg_por_m_perfil,"")) -> 4.396 | L13: =IF(E13="CHAPA_AREA",K13*INDEX('03_MATERIALES'!$H$2:$H$42,MATCH(D13,'03_MATERIALES'!$A$2:$A$42,0))/p_aprovechamiento_chapa,IF(E13="PERFIL_LONGITUD",K13*INDEX('03_MATERIALES'!$H$2:$H$42,MATCH(D13,'03_MATERIALES'!$A$2:$A$42,0))/p_aprovechamiento_perfil,IF(E13="UNIDAD",F13*INDEX('03_MATERIALES'!$H$2:$H$42,MATCH(D13,'03_MATERIALES'!$A$2:$A$42,0)),""))) -> 32.492174 | M13: =IF(N(J13)>0,F13*J13/p_area_plancha_m2,"") -> 0.097222222 | N13: ESTIMADO
A14: BOM-0013 | B14: PRD-002 | C14: Juego pernos | D14: MAT-FIJ | E14: UNIDAD | F14: 28 | K14: =IF(E14="CHAPA_AREA",F14*J14*INDEX('03_MATERIALES'!$E$2:$E$42,MATCH(D14,'03_MATERIALES'!$A$2:$A$42,0))/1000*p_densidad_acero,IF(E14="PERFIL_LONGITUD",F14*I14*p_kg_por_m_perfil,"")) | L14: =IF(E14="CHAPA_AREA",K14*INDEX('03_MATERIALES'!$H$2:$H$42,MATCH(D14,'03_MATERIALES'!$A$2:$A$42,0))/p_aprovechamiento_chapa,IF(E14="PERFIL_LONGITUD",K14*INDEX('03_MATERIALES'!$H$2:$H$42,MATCH(D14,'03_MATERIALES'!$A$2:$A$42,0))/p_aprovechamiento_perfil,IF(E14="UNIDAD",F14*INDEX('03_MATERIALES'!$H$2:$H$42,MATCH(D14,'03_MATERIALES'!$A$2:$A$42,0)),""))) -> 25.2 | M14: =IF(N(J14)>0,F14*J14/p_area_plancha_m2,"") | N14: ESTIMADO
A15: BOM-0014 | B15: PRD-007 | C15: Columna doble | D15: MAT-PR-1 | E15: PERFIL_LONGITUD | F15: 2 | I15: 1.65 | K15: =IF(E15="CHAPA_AREA",F15*J15*INDEX('03_MATERIALES'!$E$2:$E$42,MATCH(D15,'03_MATERIALES'!$A$2:$A$42,0))/1000*p_densidad_acero,IF(E15="PERFIL_LONGITUD",F15*I15*p_kg_por_m_perfil,"")) -> 4.95 | L15: =IF(E15="CHAPA_AREA",K15*INDEX('03_MATERIALES'!$H$2:$H$42,MATCH(D15,'03_MATERIALES'!$A$2:$A$42,0))/p_aprovechamiento_chapa,IF(E15="PERFIL_LONGITUD",K15*INDEX('03_MATERIALES'!$H$2:$H$42,MATCH(D15,'03_MATERIALES'!$A$2:$A$42,0))/p_aprovechamiento_perfil,IF(E15="UNIDAD",F15*INDEX('03_MATERIALES'!$H$2:$H$42,MATCH(D15,'03_MATERIALES'!$A$2:$A$42,0)),""))) -> 31.453125 | M15: =IF(N(J15)>0,F15*J15/p_area_plancha_m2,"") | N15: ESTIMADO
A16: BOM-0015 | B16: PRD-007 | C16: Base apoyo | D16: MAT-CH-1.0 | E16: CHAPA_AREA | F16: 2 | J16: 0.3 | K16: =IF(E16="CHAPA_AREA",F16*J16*INDEX('03_MATERIALES'!$E$2:$E$42,MATCH(D16,'03_MATERIALES'!$A$2:$A$42,0))/1000*p_densidad_acero,IF(E16="PERFIL_LONGITUD",F16*I16*p_kg_por_m_perfil,"")) -> 4.71 | L16: =IF(E16="CHAPA_AREA",K16*INDEX('03_MATERIALES'!$H$2:$H$42,MATCH(D16,'03_MATERIALES'!$A$2:$A$42,0))/p_aprovechamiento_chapa,IF(E16="PERFIL_LONGITUD",K16*INDEX('03_MATERIALES'!$H$2:$H$42,MATCH(D16,'03_MATERIALES'!$A$2:$A$42,0))/p_aprovechamiento_perfil,IF(E16="UNIDAD",F16*INDEX('03_MATERIALES'!$H$2:$H$42,MATCH(D16,'03_MATERIALES'!$A$2:$A$42,0)),""))) -> 34.813043 | M16: =IF(N(J16)>0,F16*J16/p_area_plancha_m2,"") -> 0.20833333 | N16: ESTIMADO
A17: BOM-0016 | B17: PRD-007 | C17: Panel trasero | D17: MAT-CH-1.0 | E17: CHAPA_AREA | F17: 4 | J17: 0.56 | K17: =IF(E17="CHAPA_AREA",F17*J17*INDEX('03_MATERIALES'!$E$2:$E$42,MATCH(D17,'03_MATERIALES'!$A$2:$A$42,0))/1000*p_densidad_acero,IF(E17="PERFIL_LONGITUD",F17*I17*p_kg_por_m_perfil,"")) -> 17.584 | L17: =IF(E17="CHAPA_AREA",K17*INDEX('03_MATERIALES'!$H$2:$H$42,MATCH(D17,'03_MATERIALES'!$A$2:$A$42,0))/p_aprovechamiento_chapa,IF(E17="PERFIL_LONGITUD",K17*INDEX('03_MATERIALES'!$H$2:$H$42,MATCH(D17,'03_MATERIALES'!$A$2:$A$42,0))/p_aprovechamiento_perfil,IF(E17="UNIDAD",F17*INDEX('03_MATERIALES'!$H$2:$H$42,MATCH(D17,'03_MATERIALES'!$A$2:$A$42,0)),""))) -> 129.9687 | M17: =IF(N(J17)>0,F17*J17/p_area_plancha_m2,"") -> 0.77777778 | N17: ESTIMADO
A18: BOM-0017 | B18: PRD-007 | C18: Estante de exposición | D18: MAT-CH-1.0 | E18: CHAPA_AREA | F18: 8 | J18: 0.4 | K18: =IF(E18="CHAPA_AREA",F18*J18*INDEX('03_MATERIALES'!$E$2:$E$42,MATCH(D18,'03_MATERIALES'!$A$2:$A$42,0))/1000*p_densidad_acero,IF(E18="PERFIL_LONGITUD",F18*I18*p_kg_por_m_perfil,"")) -> 25.12 | L18: =IF(E18="CHAPA_AREA",K18*INDEX('03_MATERIALES'!$H$2:$H$42,MATCH(D18,'03_MATERIALES'!$A$2:$A$42,0))/p_aprovechamiento_chapa,IF(E18="PERFIL_LONGITUD",K18*INDEX('03_MATERIALES'!$H$2:$H$42,MATCH(D18,'03_MATERIALES'!$A$2:$A$42,0))/p_aprovechamiento_perfil,IF(E18="UNIDAD",F18*INDEX('03_MATERIALES'!$H$2:$H$42,MATCH(D18,'03_MATERIALES'!$A$2:$A$42,0)),""))) -> 185.66957 | M18: =IF(N(J18)>0,F18*J18/p_area_plancha_m2,"") -> 1.1111111 | N18: ESTIMADO
A19: BOM-0018 | B19: PRD-007 | C19: Ménsula | D19: MAT-CH-1.0 | E19: CHAPA_AREA | F19: 16 | J19: 0.04 | K19: =IF(E19="CHAPA_AREA",F19*J19*INDEX('03_MATERIALES'!$E$2:$E$42,MATCH(D19,'03_MATERIALES'!$A$2:$A$42,0))/1000*p_densidad_acero,IF(E19="PERFIL_LONGITUD",F19*I19*p_kg_por_m_perfil,"")) -> 5.024 | L19: =IF(E19="CHAPA_AREA",K19*INDEX('03_MATERIALES'!$H$2:$H$42,MATCH(D19,'03_MATERIALES'!$A$2:$A$42,0))/p_aprovechamiento_chapa,IF(E19="PERFIL_LONGITUD",K19*INDEX('03_MATERIALES'!$H$2:$H$42,MATCH(D19,'03_MATERIALES'!$A$2:$A$42,0))/p_aprovechamiento_perfil,IF(E19="UNIDAD",F19*INDEX('03_MATERIALES'!$H$2:$H$42,MATCH(D19,'03_MATERIALES'!$A$2:$A$42,0)),""))) -> 37.133913 | M19: =IF(N(J19)>0,F19*J19/p_area_plancha_m2,"") -> 0.22222222 | N19: ESTIMADO
A20: BOM-0019 | B20: PRD-007 | C20: Zócalo frontal | D20: MAT-CH-1.0 | E20: CHAPA_AREA | F20: 2 | J20: 0.12 | K20: =IF(E20="CHAPA_AREA",F20*J20*INDEX('03_MATERIALES'!$E$2:$E$42,MATCH(D20,'03_MATERIALES'!$A$2:$A$42,0))/1000*p_densidad_acero,IF(E20="PERFIL_LONGITUD",F20*I20*p_kg_por_m_perfil,"")) -> 1.884 | L20: =IF(E20="CHAPA_AREA",K20*INDEX('03_MATERIALES'!$H$2:$H$42,MATCH(D20,'03_MATERIALES'!$A$2:$A$42,0))/p_aprovechamiento_chapa,IF(E20="PERFIL_LONGITUD",K20*INDEX('03_MATERIALES'!$H$2:$H$42,MATCH(D20,'03_MATERIALES'!$A$2:$A$42,0))/p_aprovechamiento_perfil,IF(E20="UNIDAD",F20*INDEX('03_MATERIALES'!$H$2:$H$42,MATCH(D20,'03_MATERIALES'!$A$2:$A$42,0)),""))) -> 13.925217 | M20: =IF(N(J20)>0,F20*J20/p_area_plancha_m2,"") -> 0.083333333 | N20: ESTIMADO
A21: BOM-0020 | B21: PRD-007 | C21: Pernos de ensamble | D21: MAT-FIJ | E21: UNIDAD | F21: 36 | K21: =IF(E21="CHAPA_AREA",F21*J21*INDEX('03_MATERIALES'!$E$2:$E$42,MATCH(D21,'03_MATERIALES'!$A$2:$A$42,0))/1000*p_densidad_acero,IF(E21="PERFIL_LONGITUD",F21*I21*p_kg_por_m_perfil,"")) | L21: =IF(E21="CHAPA_AREA",K21*INDEX('03_MATERIALES'!$H$2:$H$42,MATCH(D21,'03_MATERIALES'!$A$2:$A$42,0))/p_aprovechamiento_chapa,IF(E21="PERFIL_LONGITUD",K21*INDEX('03_MATERIALES'!$H$2:$H$42,MATCH(D21,'03_MATERIALES'!$A$2:$A$42,0))/p_aprovechamiento_perfil,IF(E21="UNIDAD",F21*INDEX('03_MATERIALES'!$H$2:$H$42,MATCH(D21,'03_MATERIALES'!$A$2:$A$42,0)),""))) -> 32.4 | M21: =IF(N(J21)>0,F21*J21/p_area_plancha_m2,"") | N21: ESTIMADO
A22: BOM-0021 | B22: PRD-008 | C22: Montante mural | D22: MAT-PR-1 | E22: PERFIL_LONGITUD | F22: 2 | I22: 1.9 | K22: =IF(E22="CHAPA_AREA",F22*J22*INDEX('03_MATERIALES'!$E$2:$E$42,MATCH(D22,'03_MATERIALES'!$A$2:$A$42,0))/1000*p_densidad_acero,IF(E22="PERFIL_LONGITUD",F22*I22*p_kg_por_m_perfil,"")) -> 5.7 | L22: =IF(E22="CHAPA_AREA",K22*INDEX('03_MATERIALES'!$H$2:$H$42,MATCH(D22,'03_MATERIALES'!$A$2:$A$42,0))/p_aprovechamiento_chapa,IF(E22="PERFIL_LONGITUD",K22*INDEX('03_MATERIALES'!$H$2:$H$42,MATCH(D22,'03_MATERIALES'!$A$2:$A$42,0))/p_aprovechamiento_perfil,IF(E22="UNIDAD",F22*INDEX('03_MATERIALES'!$H$2:$H$42,MATCH(D22,'03_MATERIALES'!$A$2:$A$42,0)),""))) -> 36.21875 | M22: =IF(N(J22)>0,F22*J22/p_area_plancha_m2,"") | N22: ESTIMADO
A23: BOM-0022 | B23: PRD-008 | C23: Panel de fondo | D23: MAT-CH-1.0 | E23: CHAPA_AREA | F23: 3 | J23: 0.55 | K23: =IF(E23="CHAPA_AREA",F23*J23*INDEX('03_MATERIALES'!$E$2:$E$42,MATCH(D23,'03_MATERIALES'!$A$2:$A$42,0))/1000*p_densidad_acero,IF(E23="PERFIL_LONGITUD",F23*I23*p_kg_por_m_perfil,"")) -> 12.9525 | L23: =IF(E23="CHAPA_AREA",K23*INDEX('03_MATERIALES'!$H$2:$H$42,MATCH(D23,'03_MATERIALES'!$A$2:$A$42,0))/p_aprovechamiento_chapa,IF(E23="PERFIL_LONGITUD",K23*INDEX('03_MATERIALES'!$H$2:$H$42,MATCH(D23,'03_MATERIALES'!$A$2:$A$42,0))/p_aprovechamiento_perfil,IF(E23="UNIDAD",F23*INDEX('03_MATERIALES'!$H$2:$H$42,MATCH(D23,'03_MATERIALES'!$A$2:$A$42,0)),""))) -> 95.73587 | M23: =IF(N(J23)>0,F23*J23/p_area_plancha_m2,"") -> 0.57291667 | N23: ESTIMADO
A24: BOM-0023 | B24: PRD-008 | C24: Bandeja | D24: MAT-CH-1.0 | E24: CHAPA_AREA | F24: 5 | J24: 0.42 | K24: =IF(E24="CHAPA_AREA",F24*J24*INDEX('03_MATERIALES'!$E$2:$E$42,MATCH(D24,'03_MATERIALES'!$A$2:$A$42,0))/1000*p_densidad_acero,IF(E24="PERFIL_LONGITUD",F24*I24*p_kg_por_m_perfil,"")) -> 16.485 | L24: =IF(E24="CHAPA_AREA",K24*INDEX('03_MATERIALES'!$H$2:$H$42,MATCH(D24,'03_MATERIALES'!$A$2:$A$42,0))/p_aprovechamiento_chapa,IF(E24="PERFIL_LONGITUD",K24*INDEX('03_MATERIALES'!$H$2:$H$42,MATCH(D24,'03_MATERIALES'!$A$2:$A$42,0))/p_aprovechamiento_perfil,IF(E24="UNIDAD",F24*INDEX('03_MATERIALES'!$H$2:$H$42,MATCH(D24,'03_MATERIALES'!$A$2:$A$42,0)),""))) -> 121.84565 | M24: =IF(N(J24)>0,F24*J24/p_area_plancha_m2,"") -> 0.72916667 | N24: ESTIMADO
A25: BOM-0024 | B25: PRD-008 | C25: Soporte bandeja | D25: MAT-CH-1.0 | E25: CHAPA_AREA | F25: 10 | J25: 0.04 | K25: =IF(E25="CHAPA_AREA",F25*J25*INDEX('03_MATERIALES'!$E$2:$E$42,MATCH(D25,'03_MATERIALES'!$A$2:$A$42,0))/1000*p_densidad_acero,IF(E25="PERFIL_LONGITUD",F25*I25*p_kg_por_m_perfil,"")) -> 3.14 | L25: =IF(E25="CHAPA_AREA",K25*INDEX('03_MATERIALES'!$H$2:$H$42,MATCH(D25,'03_MATERIALES'!$A$2:$A$42,0))/p_aprovechamiento_chapa,IF(E25="PERFIL_LONGITUD",K25*INDEX('03_MATERIALES'!$H$2:$H$42,MATCH(D25,'03_MATERIALES'!$A$2:$A$42,0))/p_aprovechamiento_perfil,IF(E25="UNIDAD",F25*INDEX('03_MATERIALES'!$H$2:$H$42,MATCH(D25,'03_MATERIALES'!$A$2:$A$42,0)),""))) -> 23.208696 | M25: =IF(N(J25)>0,F25*J25/p_area_plancha_m2,"") -> 0.13888889 | N25: ESTIMADO
A26: BOM-0025 | B26: PRD-008 | C26: Pie soporte | D26: MAT-CH-1.0 | E26: CHAPA_AREA | F26: 2 | J26: 0.25 | K26: =IF(E26="CHAPA_AREA",F26*J26*INDEX('03_MATERIALES'!$E$2:$E$42,MATCH(D26,'03_MATERIALES'!$A$2:$A$42,0))/1000*p_densidad_acero,IF(E26="PERFIL_LONGITUD",F26*I26*p_kg_por_m_perfil,"")) -> 3.925 | L26: =IF(E26="CHAPA_AREA",K26*INDEX('03_MATERIALES'!$H$2:$H$42,MATCH(D26,'03_MATERIALES'!$A$2:$A$42,0))/p_aprovechamiento_chapa,IF(E26="PERFIL_LONGITUD",K26*INDEX('03_MATERIALES'!$H$2:$H$42,MATCH(D26,'03_MATERIALES'!$A$2:$A$42,0))/p_aprovechamiento_perfil,IF(E26="UNIDAD",F26*INDEX('03_MATERIALES'!$H$2:$H$42,MATCH(D26,'03_MATERIALES'!$A$2:$A$42,0)),""))) -> 29.01087 | M26: =IF(N(J26)>0,F26*J26/p_area_plancha_m2,"") -> 0.17361111 | N26: ESTIMADO
A27: BOM-0026 | B27: PRD-008 | C27: Fijaciones | D27: MAT-FIJ | E27: UNIDAD | F27: 26 | K27: =IF(E27="CHAPA_AREA",F27*J27*INDEX('03_MATERIALES'!$E$2:$E$42,MATCH(D27,'03_MATERIALES'!$A$2:$A$42,0))/1000*p_densidad_acero,IF(E27="PERFIL_LONGITUD",F27*I27*p_kg_por_m_perfil,"")) | L27: =IF(E27="CHAPA_AREA",K27*INDEX('03_MATERIALES'!$H$2:$H$42,MATCH(D27,'03_MATERIALES'!$A$2:$A$42,0))/p_aprovechamiento_chapa,IF(E27="PERFIL_LONGITUD",K27*INDEX('03_MATERIALES'!$H$2:$H$42,MATCH(D27,'03_MATERIALES'!$A$2:$A$42,0))/p_aprovechamiento_perfil,IF(E27="UNIDAD",F27*INDEX('03_MATERIALES'!$H$2:$H$42,MATCH(D27,'03_MATERIALES'!$A$2:$A$42,0)),""))) -> 23.4 | M27: =IF(N(J27)>0,F27*J27/p_area_plancha_m2,"") | N27: ESTIMADO
A28: BOM-0027 | B28: PRD-013 | C28: Panel lateral | D28: MAT-CH-1.5 | E28: CHAPA_AREA | F28: 2 | J28: 0.95 | K28: =IF(E28="CHAPA_AREA",F28*J28*INDEX('03_MATERIALES'!$E$2:$E$42,MATCH(D28,'03_MATERIALES'!$A$2:$A$42,0))/1000*p_densidad_acero,IF(E28="PERFIL_LONGITUD",F28*I28*p_kg_por_m_perfil,"")) -> 22.3725 | L28: =IF(E28="CHAPA_AREA",K28*INDEX('03_MATERIALES'!$H$2:$H$42,MATCH(D28,'03_MATERIALES'!$A$2:$A$42,0))/p_aprovechamiento_chapa,IF(E28="PERFIL_LONGITUD",K28*INDEX('03_MATERIALES'!$H$2:$H$42,MATCH(D28,'03_MATERIALES'!$A$2:$A$42,0))/p_aprovechamiento_perfil,IF(E28="UNIDAD",F28*INDEX('03_MATERIALES'!$H$2:$H$42,MATCH(D28,'03_MATERIALES'!$A$2:$A$42,0)),""))) -> 165.36196 | M28: =IF(N(J28)>0,F28*J28/p_area_plancha_m2,"") -> 0.65972222 | N28: ESTIMADO
A29: BOM-0028 | B29: PRD-013 | C29: Techo/base | D29: MAT-CH-1.5 | E29: CHAPA_AREA | F29: 2 | J29: 0.35 | K29: =IF(E29="CHAPA_AREA",F29*J29*INDEX('03_MATERIALES'!$E$2:$E$42,MATCH(D29,'03_MATERIALES'!$A$2:$A$42,0))/1000*p_densidad_acero,IF(E29="PERFIL_LONGITUD",F29*I29*p_kg_por_m_perfil,"")) -> 8.2425 | L29: =IF(E29="CHAPA_AREA",K29*INDEX('03_MATERIALES'!$H$2:$H$42,MATCH(D29,'03_MATERIALES'!$A$2:$A$42,0))/p_aprovechamiento_chapa,IF(E29="PERFIL_LONGITUD",K29*INDEX('03_MATERIALES'!$H$2:$H$42,MATCH(D29,'03_MATERIALES'!$A$2:$A$42,0))/p_aprovechamiento_perfil,IF(E29="UNIDAD",F29*INDEX('03_MATERIALES'!$H$2:$H$42,MATCH(D29,'03_MATERIALES'!$A$2:$A$42,0)),""))) -> 60.922826 | M29: =IF(N(J29)>0,F29*J29/p_area_plancha_m2,"") -> 0.24305556 | N29: ESTIMADO
A30: BOM-0029 | B30: PRD-013 | C30: Panel posterior | D30: MAT-CH-1.5 | E30: CHAPA_AREA | F30: 1 | J30: 1.7 | K30: =IF(E30="CHAPA_AREA",F30*J30*INDEX('03_MATERIALES'!$E$2:$E$42,MATCH(D30,'03_MATERIALES'!$A$2:$A$42,0))/1000*p_densidad_acero,IF(E30="PERFIL_LONGITUD",F30*I30*p_kg_por_m_perfil,"")) -> 20.0175 | L30: =IF(E30="CHAPA_AREA",K30*INDEX('03_MATERIALES'!$H$2:$H$42,MATCH(D30,'03_MATERIALES'!$A$2:$A$42,0))/p_aprovechamiento_chapa,IF(E30="PERFIL_LONGITUD",K30*INDEX('03_MATERIALES'!$H$2:$H$42,MATCH(D30,'03_MATERIALES'!$A$2:$A$42,0))/p_aprovechamiento_perfil,IF(E30="UNIDAD",F30*INDEX('03_MATERIALES'!$H$2:$H$42,MATCH(D30,'03_MATERIALES'!$A$2:$A$42,0)),""))) -> 147.95543 | M30: =IF(N(J30)>0,F30*J30/p_area_plancha_m2,"") -> 0.59027778 | N30: ESTIMADO
A31: BOM-0030 | B31: PRD-013 | C31: Puerta individual | D31: MAT-CH-1.5 | E31: CHAPA_AREA | F31: 4 | J31: 0.37 | K31: =IF(E31="CHAPA_AREA",F31*J31*INDEX('03_MATERIALES'!$E$2:$E$42,MATCH(D31,'03_MATERIALES'!$A$2:$A$42,0))/1000*p_densidad_acero,IF(E31="PERFIL_LONGITUD",F31*I31*p_kg_por_m_perfil,"")) -> 17.427 | L31: =IF(E31="CHAPA_AREA",K31*INDEX('03_MATERIALES'!$H$2:$H$42,MATCH(D31,'03_MATERIALES'!$A$2:$A$42,0))/p_aprovechamiento_chapa,IF(E31="PERFIL_LONGITUD",K31*INDEX('03_MATERIALES'!$H$2:$H$42,MATCH(D31,'03_MATERIALES'!$A$2:$A$42,0))/p_aprovechamiento_perfil,IF(E31="UNIDAD",F31*INDEX('03_MATERIALES'!$H$2:$H$42,MATCH(D31,'03_MATERIALES'!$A$2:$A$42,0)),""))) -> 128.80826 | M31: =IF(N(J31)>0,F31*J31/p_area_plancha_m2,"") -> 0.51388889 | N31: ESTIMADO
A32: BOM-0031 | B32: PRD-013 | C32: Separador interior | D32: MAT-CH-1.5 | E32: CHAPA_AREA | F32: 3 | J32: 0.35 | K32: =IF(E32="CHAPA_AREA",F32*J32*INDEX('03_MATERIALES'!$E$2:$E$42,MATCH(D32,'03_MATERIALES'!$A$2:$A$42,0))/1000*p_densidad_acero,IF(E32="PERFIL_LONGITUD",F32*I32*p_kg_por_m_perfil,"")) -> 12.36375 | L32: =IF(E32="CHAPA_AREA",K32*INDEX('03_MATERIALES'!$H$2:$H$42,MATCH(D32,'03_MATERIALES'!$A$2:$A$42,0))/p_aprovechamiento_chapa,IF(E32="PERFIL_LONGITUD",K32*INDEX('03_MATERIALES'!$H$2:$H$42,MATCH(D32,'03_MATERIALES'!$A$2:$A$42,0))/p_aprovechamiento_perfil,IF(E32="UNIDAD",F32*INDEX('03_MATERIALES'!$H$2:$H$42,MATCH(D32,'03_MATERIALES'!$A$2:$A$42,0)),""))) -> 91.384239 | M32: =IF(N(J32)>0,F32*J32/p_area_plancha_m2,"") -> 0.36458333 | N32: ESTIMADO
A33: BOM-0032 | B33: PRD-013 | C33: Bisagra | D33: MAT-FIJ | E33: UNIDAD | F33: 8 | K33: =IF(E33="CHAPA_AREA",F33*J33*INDEX('03_MATERIALES'!$E$2:$E$42,MATCH(D33,'03_MATERIALES'!$A$2:$A$42,0))/1000*p_densidad_acero,IF(E33="PERFIL_LONGITUD",F33*I33*p_kg_por_m_perfil,"")) | L33: =IF(E33="CHAPA_AREA",K33*INDEX('03_MATERIALES'!$H$2:$H$42,MATCH(D33,'03_MATERIALES'!$A$2:$A$42,0))/p_aprovechamiento_chapa,IF(E33="PERFIL_LONGITUD",K33*INDEX('03_MATERIALES'!$H$2:$H$42,MATCH(D33,'03_MATERIALES'!$A$2:$A$42,0))/p_aprovechamiento_perfil,IF(E33="UNIDAD",F33*INDEX('03_MATERIALES'!$H$2:$H$42,MATCH(D33,'03_MATERIALES'!$A$2:$A$42,0)),""))) -> 7.2 | M33: =IF(N(J33)>0,F33*J33/p_area_plancha_m2,"") | N33: ESTIMADO
A34: BOM-0033 | B34: PRD-013 | C34: Cerradura | D34: MAT-FIJ | E34: UNIDAD | F34: 4 | K34: =IF(E34="CHAPA_AREA",F34*J34*INDEX('03_MATERIALES'!$E$2:$E$42,MATCH(D34,'03_MATERIALES'!$A$2:$A$42,0))/1000*p_densidad_acero,IF(E34="PERFIL_LONGITUD",F34*I34*p_kg_por_m_perfil,"")) | L34: =IF(E34="CHAPA_AREA",K34*INDEX('03_MATERIALES'!$H$2:$H$42,MATCH(D34,'03_MATERIALES'!$A$2:$A$42,0))/p_aprovechamiento_chapa,IF(E34="PERFIL_LONGITUD",K34*INDEX('03_MATERIALES'!$H$2:$H$42,MATCH(D34,'03_MATERIALES'!$A$2:$A$42,0))/p_aprovechamiento_perfil,IF(E34="UNIDAD",F34*INDEX('03_MATERIALES'!$H$2:$H$42,MATCH(D34,'03_MATERIALES'!$A$2:$A$42,0)),""))) -> 3.6 | M34: =IF(N(J34)>0,F34*J34/p_area_plancha_m2,"") | N34: ESTIMADO
A35: BOM-0034 | B35: PRD-014 | C35: Costado externo | D35: MAT-CH-1.5 | E35: CHAPA_AREA | F35: 2 | J35: 1.1 | K35: =IF(E35="CHAPA_AREA",F35*J35*INDEX('03_MATERIALES'!$E$2:$E$42,MATCH(D35,'03_MATERIALES'!$A$2:$A$42,0))/1000*p_densidad_acero,IF(E35="PERFIL_LONGITUD",F35*I35*p_kg_por_m_perfil,"")) -> 25.905 | L35: =IF(E35="CHAPA_AREA",K35*INDEX('03_MATERIALES'!$H$2:$H$42,MATCH(D35,'03_MATERIALES'!$A$2:$A$42,0))/p_aprovechamiento_chapa,IF(E35="PERFIL_LONGITUD",K35*INDEX('03_MATERIALES'!$H$2:$H$42,MATCH(D35,'03_MATERIALES'!$A$2:$A$42,0))/p_aprovechamiento_perfil,IF(E35="UNIDAD",F35*INDEX('03_MATERIALES'!$H$2:$H$42,MATCH(D35,'03_MATERIALES'!$A$2:$A$42,0)),""))) -> 191.47174 | M35: =IF(N(J35)>0,F35*J35/p_area_plancha_m2,"") -> 0.76388889 | N35: ESTIMADO
A36: BOM-0035 | B36: PRD-014 | C36: Panel techo/base | D36: MAT-CH-1.5 | E36: CHAPA_AREA | F36: 2 | J36: 0.48 | K36: =IF(E36="CHAPA_AREA",F36*J36*INDEX('03_MATERIALES'!$E$2:$E$42,MATCH(D36,'03_MATERIALES'!$A$2:$A$42,0))/1000*p_densidad_acero,IF(E36="PERFIL_LONGITUD",F36*I36*p_kg_por_m_perfil,"")) -> 11.304 | L36: =IF(E36="CHAPA_AREA",K36*INDEX('03_MATERIALES'!$H$2:$H$42,MATCH(D36,'03_MATERIALES'!$A$2:$A$42,0))/p_aprovechamiento_chapa,IF(E36="PERFIL_LONGITUD",K36*INDEX('03_MATERIALES'!$H$2:$H$42,MATCH(D36,'03_MATERIALES'!$A$2:$A$42,0))/p_aprovechamiento_perfil,IF(E36="UNIDAD",F36*INDEX('03_MATERIALES'!$H$2:$H$42,MATCH(D36,'03_MATERIALES'!$A$2:$A$42,0)),""))) -> 83.551304 | M36: =IF(N(J36)>0,F36*J36/p_area_plancha_m2,"") -> 0.33333333 | N36: ESTIMADO
A37: BOM-0036 | B37: PRD-014 | C37: Fondo | D37: MAT-CH-1.5 | E37: CHAPA_AREA | F37: 1 | J37: 1.8 | K37: =IF(E37="CHAPA_AREA",F37*J37*INDEX('03_MATERIALES'!$E$2:$E$42,MATCH(D37,'03_MATERIALES'!$A$2:$A$42,0))/1000*p_densidad_acero,IF(E37="PERFIL_LONGITUD",F37*I37*p_kg_por_m_perfil,"")) -> 21.195 | L37: =IF(E37="CHAPA_AREA",K37*INDEX('03_MATERIALES'!$H$2:$H$42,MATCH(D37,'03_MATERIALES'!$A$2:$A$42,0))/p_aprovechamiento_chapa,IF(E37="PERFIL_LONGITUD",K37*INDEX('03_MATERIALES'!$H$2:$H$42,MATCH(D37,'03_MATERIALES'!$A$2:$A$42,0))/p_aprovechamiento_perfil,IF(E37="UNIDAD",F37*INDEX('03_MATERIALES'!$H$2:$H$42,MATCH(D37,'03_MATERIALES'!$A$2:$A$42,0)),""))) -> 156.6587 | M37: =IF(N(J37)>0,F37*J37/p_area_plancha_m2,"") -> 0.625 | N37: ESTIMADO
A38: BOM-0037 | B38: PRD-014 | C38: Puerta con rejilla | D38: MAT-CH-1.5 | E38: CHAPA_AREA | F38: 6 | J38: 0.3 | K38: =IF(E38="CHAPA_AREA",F38*J38*INDEX('03_MATERIALES'!$E$2:$E$42,MATCH(D38,'03_MATERIALES'!$A$2:$A$42,0))/1000*p_densidad_acero,IF(E38="PERFIL_LONGITUD",F38*I38*p_kg_por_m_perfil,"")) -> 21.195 | L38: =IF(E38="CHAPA_AREA",K38*INDEX('03_MATERIALES'!$H$2:$H$42,MATCH(D38,'03_MATERIALES'!$A$2:$A$42,0))/p_aprovechamiento_chapa,IF(E38="PERFIL_LONGITUD",K38*INDEX('03_MATERIALES'!$H$2:$H$42,MATCH(D38,'03_MATERIALES'!$A$2:$A$42,0))/p_aprovechamiento_perfil,IF(E38="UNIDAD",F38*INDEX('03_MATERIALES'!$H$2:$H$42,MATCH(D38,'03_MATERIALES'!$A$2:$A$42,0)),""))) -> 156.6587 | M38: =IF(N(J38)>0,F38*J38/p_area_plancha_m2,"") -> 0.625 | N38: ESTIMADO
A39: BOM-0038 | B39: PRD-014 | C39: Separador vertical | D39: MAT-CH-1.5 | E39: CHAPA_AREA | F39: 2 | J39: 0.7 | K39: =IF(E39="CHAPA_AREA",F39*J39*INDEX('03_MATERIALES'!$E$2:$E$42,MATCH(D39,'03_MATERIALES'!$A$2:$A$42,0))/1000*p_densidad_acero,IF(E39="PERFIL_LONGITUD",F39*I39*p_kg_por_m_perfil,"")) -> 16.485 | L39: =IF(E39="CHAPA_AREA",K39*INDEX('03_MATERIALES'!$H$2:$H$42,MATCH(D39,'03_MATERIALES'!$A$2:$A$42,0))/p_aprovechamiento_chapa,IF(E39="PERFIL_LONGITUD",K39*INDEX('03_MATERIALES'!$H$2:$H$42,MATCH(D39,'03_MATERIALES'!$A$2:$A$42,0))/p_aprovechamiento_perfil,IF(E39="UNIDAD",F39*INDEX('03_MATERIALES'!$H$2:$H$42,MATCH(D39,'03_MATERIALES'!$A$2:$A$42,0)),""))) -> 121.84565 | M39: =IF(N(J39)>0,F39*J39/p_area_plancha_m2,"") -> 0.48611111 | N39: ESTIMADO
A40: BOM-0039 | B40: PRD-014 | C40: Entrepiso | D40: MAT-CH-1.5 | E40: CHAPA_AREA | F40: 4 | J40: 0.4 | K40: =IF(E40="CHAPA_AREA",F40*J40*INDEX('03_MATERIALES'!$E$2:$E$42,MATCH(D40,'03_MATERIALES'!$A$2:$A$42,0))/1000*p_densidad_acero,IF(E40="PERFIL_LONGITUD",F40*I40*p_kg_por_m_perfil,"")) -> 18.84 | L40: =IF(E40="CHAPA_AREA",K40*INDEX('03_MATERIALES'!$H$2:$H$42,MATCH(D40,'03_MATERIALES'!$A$2:$A$42,0))/p_aprovechamiento_chapa,IF(E40="PERFIL_LONGITUD",K40*INDEX('03_MATERIALES'!$H$2:$H$42,MATCH(D40,'03_MATERIALES'!$A$2:$A$42,0))/p_aprovechamiento_perfil,IF(E40="UNIDAD",F40*INDEX('03_MATERIALES'!$H$2:$H$42,MATCH(D40,'03_MATERIALES'!$A$2:$A$42,0)),""))) -> 139.25217 | M40: =IF(N(J40)>0,F40*J40/p_area_plancha_m2,"") -> 0.55555556 | N40: ESTIMADO
...

Sheet 05_RECURSOS
A1: recurso_id | B1: recurso | C1: tipo_tecnico | D1: tipo_recurso | E1: cantidad | F1: costo_uso_soles_h | G1: potencia_kw_ref | H1: factor_carga | I1: grupo_operarios | J1: recurso_critico | K1: inventario_verificado | L1: naturaleza
A2: CCH-01 | B2: Guillotina hidráulica para corte de planchas de acero | C2: Guillotina hidráulica de chapa, hasta 4 mm | D2: MAQUINA | E2: 1 | F2: 24 | G2: 5.5 | H2: 0.5 | I2: Corte | J2: 0 | K2: 0 | L2: ESTIMADO
A3: CPR-01 | B3: Sierra de cinta para corte de tubos y perfiles | C3: Sierra de cinta para metal | D3: MAQUINA | E3: 1 | F3: 22 | G3: 0.75 | H3: 0.6 | I3: Corte | J3: 0 | K3: 0 | L3: ESTIMADO
A4: PER-01 | B4: Taladro de banco para perforación de acero | C4: Taladro de banco industrial | D4: MAQUINA | E4: 1 | F4: 22 | G4: 0.55 | H4: 0.5 | I4: Perforación | J4: 0 | K4: 0 | L4: ESTIMADO
A5: PLE-01 | B5: Plegadora hidráulica de chapa metálica | C5: Plegadora hidráulica compacta | D5: MAQUINA | E5: 1 | F5: 28 | G5: 5.5 | H5: 0.45 | I5: Plegado | J5: 1 | K5: 0 | L5: ESTIMADO
A6: SOL-01 | B6: Máquina de soldadura por arco MIG/MAG | C6: Soldadora inversora MIG/MAG | D6: MAQUINA | E6: 1 | F6: 32 | G6: 5 | H6: 0.35 | I6: Soldadura y armado | J6: 0 | K6: 0 | L6: ESTIMADO
A7: DES-01 | B7: Mesa de desbarbado/esmerilado | C7: Mesa de desbarbado/esmerilado | D7: PUESTO_MANUAL | E7: 1 | F7: 21 | G7: 1.5 | H7: 0.5 | I7: Acabado | J7: 0 | K7: 0 | L7: ESTIMADO
A8: PRE-01 | B8: Zona de preparación superficial | C8: Zona de preparación superficial | D8: AREA | E8: 1 | F8: 19 | G8: 2.2 | H8: 0.4 | I8: Acabado | J8: 0 | K8: 0 | L8: ESTIMADO
A9: PIN-01 | B9: Pistola manual de pintura electrostática en polvo | C9: Pistola manual de pintura electrostática en polvo | D9: EQUIPO_MANUAL | E9: 1 | F9: 32 | G9: 1.5 | H9: 0.7 | I9: Pintura y curado | J9: 0 | K9: 0 | L9: ESTIMADO
A10: ARM-01 | B10: Mesa de armado | C10: Mesa de armado | D10: PUESTO_MANUAL | E10: 1 | F10: 19 | G10: 1 | H10: 0.3 | I10: Soldadura y armado | J10: 0 | K10: 0 | L10: ESTIMADO
A11: CAL-01 | B11: Área de inspección | C11: Área de inspección | D11: AREA | E11: 1 | F11: 20 | G11: 0.2 | H11: 0.5 | I11: Calidad y despacho | J11: 0 | K11: 0 | L11: ESTIMADO
A12: EMP-01 | B12: Zona de protección y embalaje | C12: Zona de protección y embalaje | D12: AREA | E12: 1 | F12: 18 | G12: 0.3 | H12: 0.3 | I12: Calidad y despacho | J12: 0 | K12: 0 | L12: ESTIMADO
A13: PER-02 | B13: Segundo taladro (alternativo) | C13: Segundo taladro (alternativo) | D13: MAQUINA | E13: 1 | F13: 22 | G13: 0.75 | H13: 0.5 | I13: Perforación | J13: 0 | K13: 0 | L13: ESTIMADO
A14: SOL-02 | B14: Segunda estación soldadura (alternativa) | C14: Segunda estación soldadura (alternativa) | D14: MAQUINA | E14: 1 | F14: 32 | G14: 5 | H14: 0.35 | I14: Soldadura y armado | J14: 0 | K14: 0 | L14: ESTIMADO
A15: PIN-EXT | B15: Proveedor de pintura externo | C15: Proveedor de pintura externo | D15: EXTERNO | E15: 0 | G15: 0 | H15: 0 | I15: No aplica | J15: 0 | K15: 0 | L15: ESTIMADO
A16: HOR-01 | B16: Horno de curado de pintura electrostática por lotes | C16: Horno de curado de pintura electrostática por lotes | D16: MAQUINA | E16: 1 | F16: 26 | G16: 24 | H16: 0.6 | I16: Pintura y curado | J16: 0 | K16: 0 | L16: ESTIMADO
A17: MAN-01 | B17: Manipulación y enfriamiento de piezas | C17: Manipulación y enfriamiento de piezas | D17: PUESTO_MANUAL | E17: 1 | F17: 16 | G17: 0.5 | H17: 0.5 | I17: Pintura y curado | J17: 0 | K17: 0 | L17: ESTIMADO
A18: SAL-PIN | B18: Sala acondicionada para pintura electrostática | C18: Sala acondicionada para pintura electrostática | D18: AREA | E18: 1 | G18: 3 | H18: 0.5 | I18: Pintura y curado | J18: 0 | K18: 0 | L18: ESTIMADO

Sheet 06_RUTAS
A1: producto_id | B1: paso | C1: operacion | D1: recurso_id | E1: paso_predecesor | F1: min_fijos_lote | G1: min_por_unidad | H1: tratamiento_tiempo | I1: min_ciclo_horno_incluido | J1: origen_tiempo | K1: naturaleza
A2: PRD-001 | B2: 1 | C2: Corte de planchas de acero | D2: CCH-01 | F2: 8 | G2: 34.62 | H2: POR_UNIDAD | I2: 0 | J2: HEREDADO_SIN_CRONOMETRAJE | K2: ESTIMADO
A3: PRD-001 | B3: 2 | C3: Corte de tubos y perfiles | D3: CPR-01 | E3: 1 | F3: 8 | G3: 43.52 | H3: POR_UNIDAD | I3: 0 | J3: HEREDADO_SIN_CRONOMETRAJE | K3: ESTIMADO
A4: PRD-001 | B4: 3 | C4: Perforación | D4: PER-01 | E4: 2 | F4: 10 | G4: 63.2 | H4: POR_UNIDAD | I4: 0 | J4: HEREDADO_SIN_CRONOMETRAJE | K4: ESTIMADO
A5: PRD-001 | B5: 4 | C5: Plegado | D5: PLE-01 | E5: 3 | F5: 12 | G5: 60 | H5: POR_UNIDAD | I5: 0 | J5: HEREDADO_SIN_CRONOMETRAJE | K5: ESTIMADO
A6: PRD-001 | B6: 5 | C6: Soldadura | D6: SOL-01 | E6: 4 | F6: 10 | G6: 78.4 | H6: POR_UNIDAD | I6: 0 | J6: HEREDADO_SIN_CRONOMETRAJE | K6: ESTIMADO
A7: PRD-001 | B7: 6 | C7: Desbarbado | D7: DES-01 | E7: 5 | F7: 3 | G7: 42 | H7: POR_UNIDAD | I7: 0 | J7: HEREDADO_SIN_CRONOMETRAJE | K7: ESTIMADO
A8: PRD-001 | B8: 7 | C8: Preparación superficial | D8: PRE-01 | E8: 6 | F8: 6 | G8: 29.7248 | H8: POR_UNIDAD | I8: 0 | J8: HEREDADO_SIN_CRONOMETRAJE | K8: ESTIMADO
A9: PRD-001 | B9: 8 | C9: Aplicación electrostática de polvo | D9: PIN-01 | E9: 7 | F9: 12 | G9: 8.02 | H9: POR_UNIDAD | I9: 0 | J9: HIPOTESIS_TECNICA | K9: ESTIMADO
A10: PRD-001 | B10: 9 | C10: Curado térmico en horno | D10: HOR-01 | E10: 8 | F10: 45 | G10: 0 | H10: POR_LOTE | I10: 40 | J10: HIPOTESIS_TECNICA | K10: ESTIMADO
A11: PRD-001 | B11: 10 | C11: Colgado, traslado y enfriamiento | D11: MAN-01 | E11: 9 | F11: 8 | G11: 2.69 | H11: POR_UNIDAD | I11: 0 | J11: HIPOTESIS_TECNICA | K11: ESTIMADO
A12: PRD-001 | B12: 11 | C12: Ensamblaje | D12: ARM-01 | E12: 10 | F12: 6 | G12: 60 | H12: POR_UNIDAD | I12: 0 | J12: HEREDADO_SIN_CRONOMETRAJE | K12: ESTIMADO
A13: PRD-001 | B13: 12 | C13: Inspección de calidad | D13: CAL-01 | E13: 11 | F13: 2 | G13: 3.86 | H13: POR_UNIDAD | I13: 0 | J13: HIPOTESIS_TECNICA | K13: ESTIMADO
A14: PRD-001 | B14: 13 | C14: Embalaje | D14: EMP-01 | E14: 12 | F14: 2 | G14: 5.3 | H14: POR_UNIDAD | I14: 0 | J14: HIPOTESIS_TECNICA | K14: ESTIMADO
A15: PRD-002 | B15: 1 | C15: Corte de planchas de acero | D15: CCH-01 | F15: 8 | G15: 36.67 | H15: POR_UNIDAD | I15: 0 | J15: HEREDADO_SIN_CRONOMETRAJE | K15: ESTIMADO
A16: PRD-002 | B16: 2 | C16: Corte de tubos y perfiles | D16: CPR-01 | E16: 1 | F16: 8 | G16: 52 | H16: POR_UNIDAD | I16: 0 | J16: HEREDADO_SIN_CRONOMETRAJE | K16: ESTIMADO
A17: PRD-002 | B17: 3 | C17: Perforación | D17: PER-01 | E17: 2 | F17: 10 | G17: 82.1 | H17: POR_UNIDAD | I17: 0 | J17: HEREDADO_SIN_CRONOMETRAJE | K17: ESTIMADO
A18: PRD-002 | B18: 4 | C18: Plegado | D18: PLE-01 | E18: 3 | F18: 12 | G18: 69 | H18: POR_UNIDAD | I18: 0 | J18: HEREDADO_SIN_CRONOMETRAJE | K18: ESTIMADO
A19: PRD-002 | B19: 5 | C19: Soldadura | D19: SOL-01 | E19: 4 | F19: 10 | G19: 78.4 | H19: POR_UNIDAD | I19: 0 | J19: HEREDADO_SIN_CRONOMETRAJE | K19: ESTIMADO
A20: PRD-002 | B20: 6 | C20: Desbarbado | D20: DES-01 | E20: 5 | F20: 3 | G20: 49.5 | H20: POR_UNIDAD | I20: 0 | J20: HEREDADO_SIN_CRONOMETRAJE | K20: ESTIMADO
A21: PRD-002 | B21: 7 | C21: Preparación superficial | D21: PRE-01 | E21: 6 | F21: 6 | G21: 32.064 | H21: POR_UNIDAD | I21: 0 | J21: HEREDADO_SIN_CRONOMETRAJE | K21: ESTIMADO
A22: PRD-002 | B22: 8 | C22: Aplicación electrostática de polvo | D22: PIN-01 | E22: 7 | F22: 12 | G22: 8.02 | H22: POR_UNIDAD | I22: 0 | J22: HIPOTESIS_TECNICA | K22: ESTIMADO
A23: PRD-002 | B23: 9 | C23: Curado térmico en horno | D23: HOR-01 | E23: 8 | F23: 45 | G23: 0 | H23: POR_LOTE | I23: 40 | J23: HIPOTESIS_TECNICA | K23: ESTIMADO
A24: PRD-002 | B24: 10 | C24: Colgado, traslado y enfriamiento | D24: MAN-01 | E24: 9 | F24: 8 | G24: 2.69 | H24: POR_UNIDAD | I24: 0 | J24: HIPOTESIS_TECNICA | K24: ESTIMADO
A25: PRD-002 | B25: 11 | C25: Ensamblaje | D25: ARM-01 | E25: 10 | F25: 6 | G25: 62.25 | H25: POR_UNIDAD | I25: 0 | J25: HEREDADO_SIN_CRONOMETRAJE | K25: ESTIMADO
A26: PRD-002 | B26: 12 | C26: Inspección de calidad | D26: CAL-01 | E26: 11 | F26: 2 | G26: 3.86 | H26: POR_UNIDAD | I26: 0 | J26: HIPOTESIS_TECNICA | K26: ESTIMADO
A27: PRD-002 | B27: 13 | C27: Embalaje | D27: EMP-01 | E27: 12 | F27: 2 | G27: 5.3 | H27: POR_UNIDAD | I27: 0 | J27: HIPOTESIS_TECNICA | K27: ESTIMADO
A28: PRD-007 | B28: 1 | C28: Corte de planchas de acero | D28: CCH-01 | F28: 8 | G28: 90.38 | H28: POR_UNIDAD | I28: 0 | J28: HEREDADO_SIN_CRONOMETRAJE | K28: ESTIMADO
A29: PRD-007 | B29: 2 | C29: Corte de tubos y perfiles | D29: CPR-01 | E29: 1 | F29: 8 | G29: 5.98 | H29: POR_UNIDAD | I29: 0 | J29: HEREDADO_SIN_CRONOMETRAJE | K29: ESTIMADO
A30: PRD-007 | B30: 3 | C30: Perforación | D30: PER-01 | E30: 2 | F30: 10 | G30: 97 | H30: POR_UNIDAD | I30: 0 | J30: HEREDADO_SIN_CRONOMETRAJE | K30: ESTIMADO
A31: PRD-007 | B31: 4 | C31: Plegado | D31: PLE-01 | E31: 3 | F31: 12 | G31: 196 | H31: POR_UNIDAD | I31: 0 | J31: HEREDADO_SIN_CRONOMETRAJE | K31: ESTIMADO
A32: PRD-007 | B32: 5 | C32: Desbarbado | D32: DES-01 | E32: 4 | F32: 3 | G32: 51 | H32: POR_UNIDAD | I32: 0 | J32: HEREDADO_SIN_CRONOMETRAJE | K32: ESTIMADO
A33: PRD-007 | B33: 6 | C33: Preparación superficial | D33: PRE-01 | E33: 5 | F33: 6 | G33: 40.5152 | H33: POR_UNIDAD | I33: 0 | J33: HEREDADO_SIN_CRONOMETRAJE | K33: ESTIMADO
A34: PRD-007 | B34: 7 | C34: Aplicación electrostática de polvo | D34: PIN-01 | E34: 6 | F34: 12 | G34: 7.76 | H34: POR_UNIDAD | I34: 0 | J34: HIPOTESIS_TECNICA | K34: ESTIMADO
A35: PRD-007 | B35: 8 | C35: Curado térmico en horno | D35: HOR-01 | E35: 7 | F35: 45 | G35: 0 | H35: POR_LOTE | I35: 40 | J35: HIPOTESIS_TECNICA | K35: ESTIMADO
A36: PRD-007 | B36: 9 | C36: Colgado, traslado y enfriamiento | D36: MAN-01 | E36: 8 | F36: 8 | G36: 2.63 | H36: POR_UNIDAD | I36: 0 | J36: HIPOTESIS_TECNICA | K36: ESTIMADO
A37: PRD-007 | B37: 10 | C37: Ensamblaje | D37: ARM-01 | E37: 9 | F37: 6 | G37: 69 | H37: POR_UNIDAD | I37: 0 | J37: HEREDADO_SIN_CRONOMETRAJE | K37: ESTIMADO
A38: PRD-007 | B38: 11 | C38: Inspección de calidad | D38: CAL-01 | E38: 10 | F38: 2 | G38: 3.79 | H38: POR_UNIDAD | I38: 0 | J38: HIPOTESIS_TECNICA | K38: ESTIMADO
A39: PRD-007 | B39: 12 | C39: Embalaje | D39: EMP-01 | E39: 11 | F39: 2 | G39: 5.18 | H39: POR_UNIDAD | I39: 0 | J39: HIPOTESIS_TECNICA | K39: ESTIMADO
A40: PRD-008 | B40: 1 | C40: Corte de planchas de acero | D40: CCH-01 | F40: 8 | G40: 56.975 | H40: POR_UNIDAD | I40: 0 | J40: HEREDADO_SIN_CRONOMETRAJE | K40: ESTIMADO
...

Sheet 07_ELEGIBILIDAD
A1: producto_id | B1: paso | C1: recurso_id | D1: tipo_asignacion | E1: elegible | F1: factor_tiempo | G1: naturaleza
A2: PRD-001 | B2: 1 | C2: CCH-01 | D2: PRINCIPAL | E2: 1 | F2: 1 | G2: CALCULADO
A3: PRD-001 | B3: 2 | C3: CPR-01 | D3: PRINCIPAL | E3: 1 | F3: 1 | G3: CALCULADO
A4: PRD-001 | B4: 3 | C4: PER-01 | D4: PRINCIPAL | E4: 1 | F4: 1 | G4: CALCULADO
A5: PRD-001 | B5: 3 | C5: PER-02 | D5: ALT_UTILLAJE | E5: 1 | F5: 1.1 | G5: ESTIMADO
A6: PRD-001 | B6: 4 | C6: PLE-01 | D6: PRINCIPAL | E6: 1 | F6: 1 | G6: CALCULADO
A7: PRD-001 | B7: 5 | C7: SOL-01 | D7: PRINCIPAL | E7: 1 | F7: 1 | G7: CALCULADO
A8: PRD-001 | B8: 5 | C8: SOL-02 | D8: ALT_MISMO_PROCESO | E8: 1 | F8: 1 | G8: ESTIMADO
A9: PRD-001 | B9: 6 | C9: DES-01 | D9: PRINCIPAL | E9: 1 | F9: 1 | G9: CALCULADO
A10: PRD-001 | B10: 7 | C10: PRE-01 | D10: PRINCIPAL | E10: 1 | F10: 1 | G10: CALCULADO
A11: PRD-001 | B11: 8 | C11: PIN-01 | D11: PRINCIPAL | E11: 1 | F11: 1 | G11: CALCULADO
A12: PRD-001 | B12: 9 | C12: HOR-01 | D12: PRINCIPAL | E12: 1 | F12: 1 | G12: CALCULADO
A13: PRD-001 | B13: 10 | C13: MAN-01 | D13: PRINCIPAL | E13: 1 | F13: 1 | G13: CALCULADO
... A474: PRD-050 | B474: 8 | C474: ARM-01 | D474: PRINCIPAL | E474: 1 | F474: 1 | G474: CALCULADO

Sheet 08_PERSONAL
